Workbook
Name AU_faculty_dep: AU_deps[#Headers]
Name BenchFeeFoundation: AU!$H$10
Name BenchFeePartner1: AU!$I$120
Name CoFinVIPCat: Lists!$N$34:$N$45
Name DateFormat: AU!$D$10
Name Dep_list: INDEX(AU_deps[],,MATCH(Faculty_AU,AU_faculty_dep,0))
Name DepPartner1: AU!$D$7
Name endDate: AU!$D$9
Name ExtrapolationFactorPartner1: IF(AND(DateFormat="Project years",AU!$F$12<>""),AU!$F$12,AU!$H$1)
Name Faculty_AU: AU!$D$6
Name FacultyPartner1: AU!$D$6
Name Foundation: AU!$D$12
Name Foundationdropdown: Lists!$W$2:$W$15
Name IfDay: IF(DATEDIF(startDate,endDate,"md")=1," day"," days")
Name IfMonth: IF(DATEDIF(startDate,endDate,"ym")=1," month"," months")
Name IfYear: IF(DATEDIF(startDate,endDate,"y")=1," year"," years")
Name Institutiondropdown: Lists!$A$2:$A$10
Name InstitutionPartner1: AU!$D$5
Name Nat_AU_deps: Lists!$C$36:$C$43
Name NNFDisseminationCosts: Lists!$Q$23:$Q$26
Name NNFOperationCosts: Lists!$Q$17:$Q$20
Name OHFoundation: Lists!$X$2:$X$15
Name OHPctCoFinancePartner1: AU!$F$163
Name OHPctPartner1: AU!$D$13
Name OHTerm: Lists!$Y$2:$Y$15
Name PhD_navn: Lists!$N$10
Name PLPartner1: AU!$D$11
Name Project_supplement_foundations: Lists!$W$18:$W$26
Name Project_supplement_institutions: Lists!$A$2:$A$9
Name ProjectCosts: Lists!$Q$2:$Q$13
Name ProjectSupplementPartner1: AU!$H$6
Name SalaryYearPartner1: AU!$H$2
Name SciAreaPartner1: AU!$D$6
Name startDate: AU!$D$8
Name TAPCat: Lists!$N$21:$N$31
Name TuitionFeePartner1: AU!$H$8
Name VIPCat: Lists!$N$2:$N$17

Sheet Guide
B1: Getting started with the "NNF Budget template"
B2: • | C2: Fill in the yellow fields - see an example in the picture to the right. (Only the yellow fields can be edited, the rest are protected).
B3: • | C3: Whenever you see an info-icon, like the one to the right, you can hover the mouse over the icon and read a guiding text.
B5: • | C5: If you need to budget more than 6 project years, press the "plus sign" in the very top of the budget template - see picture to the right. (The template by default starts with only 6 budget years visible).
B12: • | C12: If you have filled in all of the visible budget rows in the template, more rows can be accessed by pressing the "plus sign" in the left side.
B16: Guide
B17: • | C17: Remember to fill in all master data regarding the project. All projects must have a start and end date (awards can in a few cases be exempted from this). | H17: For NORMA - this tab you can use for a more to copy/paste-friendly layout of your final and approved budget when you have to enter it into the official NNF application system, Norma. Always ensure the final budget numbers you enter into NORMA are correct and correspond to the ones from the approved budget.
B18: • | C18: Wage estimates for personnel: For each employment category selected, the template will by default show the average AU salary for that position, if one is available (see tab "AU salary costs 2025"). You can overwrite this. You should strive to use the actual salary costs where possible for named, already employed persons.
B19: • | C19: Project supplement: After intensive work between private Danish foundations (Lundbeck, Novo, Leo, Velux, Villum and Carlsberg) and the collected Universities in Denmark, there has been an agreement regarding bigger contributions to the Universities' costs of having an external contribution. These project supplements are given based on specific personnel categories and are in the template calculated automatically for the foundations that have agreed to this support. The support for STEM fields is 250.000 DKK per 12 months, full time employed (FTE) postdoc, PhD or Scientific Assistant. It does involve a few additional personnel categories - the so called VIP group C - which can be selected as well. The calculation in the template adds the amount to the collected requested budget and will adjust for partial FTE. For instance, half a PhD for year one will be automatically calculated to 125.000 DKK if it is for one of the metioned foundations, making it easier to add these fixed costs to your budget. See the official guidelines for further explanation of project supplement.
C20: Link to agreement (Danish): Aftale med fonde om finansiering af forskningsprojekter - Danske Universiteter
C21: Link to agreement (English): eng_aftaletekst_endelig_final.pdf
C22: Link to Danish guide to project supplement (Ver 3): https://dkuni.dk/wp-content/uploads/2025/12/vejledning-projekttillaeg-version-3.pdf
C23: Link to English guide to project supplement (Ver 3): https://dkuni.dk/wp-content/uploads/2025/12/guidelines-for-project-supplement_final_version-3.pdf
B24: • | C24: Project overhead (OH) or Indirect costs/Administrative support is automatically calculated in the budget template, as the product of the entered overhead percentage (if any) and the sum of all the costs.
B25: • | C25: Project costs: Can be entered applied in the section section entitled 'Project costs'. There is attributed a general categorization of the consumables, but otherwise we advise that the notes are used to futher subcategorize the consumables in the degree that it is necessary.
B26: • | C26: Purchase of departmental services (in danish: "Inddækning") This can include hiring of technicians or use of infrastructure specifically for the project - services that are available at your department the costs of which need to be covered by the project. Ask your department which items counts towards this in your budget.
B27: • | C27: Co-financing is where the University (your department) is funding costs directly related to the project. Ask your department regarding this category. All co-financing has to be cleared by your department before applying.
B29: FAQ
C30: Frequently asked question | D30: Answer
B31: • | C31: Will be filled out continuously
B32: •
B33: •
B34: •
B35: •
B36: •
B37: •
B38: •
B39: •
B40: •
B41: •

Sheet AU
G1: Extrapolation factor (default): | H1: =IFERROR(IF(AND(DateFormat="Project years",MONTH($L$1)>6),((YEAR($L$1)+1)-YEAR(SalaryYearPartner1)),(YEAR($L$2)-YEAR(SalaryYearPartner1))),1) -> 2 | K1: Dates Project years | L1: {=IF(startDate="",e,startDate)} -> 46296 | N1: =IF(L1<endDate,MIN(EDATE(L1,12)-1,endDate),"") -> 46660 | O1: =IF(N1<endDate,N1+1,"") -> 46661 | Q1: =IF(O1<endDate,MIN(EDATE(O1,12)-1,endDate),"") -> 47026 | R1: =IF(Q1<endDate,Q1+1,"") -> 47027 | T1: =IF(R1<endDate,MIN(EDATE(R1,12)-1,endDate),"") -> 47391 | U1: =IF(T1<endDate,T1+1,"") -> 47392 | W1: =IF(U1<endDate,MIN(EDATE(U1,12)-1,endDate),"") -> 47756 | X1: =IF(W1<endDate,W1+1,"") -> 47757 | Z1: =IF(X1<endDate,MIN(EDATE(X1,12)-1,endDate),"") -> 48121 | AA1: =IF(Z1<endDate,Z1+1,"") -> 48122 | AC1: =IF(AA1<endDate,MIN(EDATE(AA1,12)-1,endDate),"") -> 48487 | AD1: =IF(AC1<endDate,AC1+1,"") | AF1: =IF(AD1<endDate,MIN(EDATE(AD1,12)-1,endDate),"") | AG1: =IF(AF1<endDate,AF1+1,"") | AI1: =IF(AG1<endDate,MIN(EDATE(AG1,12)-1,endDate),"") | AJ1: =IF(AI1<endDate,AI1+1,"") | AL1: =IF(AJ1<endDate,MIN(EDATE(AJ1,12)-1,endDate),"") | AM1: =IF(AL1<endDate,AL1+1,"") | AO1: =IF(AM1<endDate,MIN(EDATE(AM1,12)-1,endDate),"")
G2: Salary year: | H2: 45658 | K2: Dates Calendar years | L2: {=IF(startDate="",e,startDate)} -> 46296 | N2: =IF(L2<endDate,MIN(endDate,DATE(YEAR(L2),12,31)),"") -> 46387 | O2: =IF(N2<endDate,N2+1,"") -> 46388 | Q2: =IF(O2<endDate,MIN(endDate,DATE(YEAR(O2),12,31)),"") -> 46752 | R2: =IF(Q2<endDate,Q2+1,"") -> 46753 | T2: =IF(R2<endDate,MIN(endDate,DATE(YEAR(R2),12,31)),"") -> 47118 | U2: =IF(T2<endDate,T2+1,"") -> 47119 | W2: =IF(U2<endDate,MIN(endDate,DATE(YEAR(U2),12,31)),"") -> 47483 | X2: =IF(W2<endDate,W2+1,"") -> 47484 | Z2: =IF(X2<endDate,MIN(endDate,DATE(YEAR(X2),12,31)),"") -> 47848 | AA2: =IF(Z2<endDate,Z2+1,"") -> 47849 | AC2: =IF(AA2<endDate,MIN(endDate,DATE(YEAR(AA2),12,31)),"") -> 48213 | AD2: =IF(AC2<endDate,AC2+1,"") -> 48214 | AF2: =IF(AD2<endDate,MIN(endDate,DATE(YEAR(AD2),12,31)),"") -> 48487 | AG2: =IF(AF2<endDate,AF2+1,"") | AI2: =IF(AG2<endDate,MIN(endDate,DATE(YEAR(AG2),12,31)),"") | AJ2: =IF(AI2<endDate,AI2+1,"") | AL2: =IF(AJ2<endDate,MIN(endDate,DATE(YEAR(AJ2),12,31)),"") | AM2: =IF(AL2<endDate,AL2+1,"") | AO2: =IF(AM2<endDate,MIN(endDate,DATE(YEAR(AM2),12,31)),"")
K3: Year number | N3: =ExtrapolationFactorPartner1 -> 2 | Q3: =ExtrapolationFactorPartner1+1 -> 3 | T3: =ExtrapolationFactorPartner1+2 -> 4 | W3: =ExtrapolationFactorPartner1+3 -> 5 | Z3: =ExtrapolationFactorPartner1+4 -> 6 | AC3: =ExtrapolationFactorPartner1+5 -> 7 | AF3: =ExtrapolationFactorPartner1+6 -> 8 | AI3: =ExtrapolationFactorPartner1+7 -> 9 | AL3: =ExtrapolationFactorPartner1+8 -> 10 | AO3: =ExtrapolationFactorPartner1+9 -> 11
B4: Template version: 08-01-2026 | J4: NNF NERD template
B5: Institution | D5: AU | J5: Link to call: | K5: New Exploratory Research and Discovery (NERD) Programme 2026 - Novo Nordisk Fonden
B6: =IFERROR(IF(InstitutionPartner1="AU","Faculty","Scientific Area"),"Faculty") -> Faculty | D6: Natural Sciences | G6: Project supplement: | H6: =IF(InstitutionPartner1="AU",_xlfn.XLOOKUP(FacultyPartner1,Lists!C:C,Lists!E:E),_xlfn.XLOOKUP(SciAreaPartner1,Lists!C:C,Lists!E:E)) -> 250000
B7: Department | D7: MBG
B8: Project start date | D8: 46296 | F8: Tuition fee/year/PhD: | G8: Tuition fee: | H8: =IF(AND(InstitutionPartner1="AU",$F$9=0,Foundation<>"DFF"),_xlfn.XLOOKUP(FacultyPartner1,Lists!C:C,Lists!F:F),IF(AND(InstitutionPartner1="AU",$F$9=0,Foundation="DFF"),_xlfn.XLOOKUP(FacultyPartner1,Lists!C:C,Lists!G:G),$F$9)) -> 80000 | J8: Earliest start: 1 August 2026
B9: Project end date | D9: 48487 | F9: =IF(AND(InstitutionPartner1="AU",Foundation<>"DFF"),_xlfn.XLOOKUP(FacultyPartner1,Lists!C:C,Lists!F:F),IF(AND(InstitutionPartner1="AU",Foundation="DFF"),_xlfn.XLOOKUP(FacultyPartner1,Lists!C:C,Lists!G:G),"")) -> 80000 | J9: Latest start: 1 February 2027
B10: Date format | D10: Project years | G10: Bench fee | H10: =IFERROR(IF(_xlfn.XLOOKUP(Foundation,Foundationdropdown,Lists!Z2:Z15)=0,$F$183,_xlfn.XLOOKUP(Foundation,Foundationdropdown,Lists!Z2:Z15)),"") -> 8000
B11: Salary yearly extrapolation | D11: 0.03 | F11: Extrapolation 1st year: | J11: Amount: | K11: Up to DKK 16 million
B12: Foundation | D12: Novo Nordisk | F12: =IFERROR(IF(AND(DateFormat="Project years",MONTH($L$1)>6),((YEAR($L$1)+1)-YEAR(SalaryYearPartner1)),(YEAR($L$2)-YEAR(SalaryYearPartner1))),1) -> 2 | J12: Duration: | K12: 6 years (min. 5)
B13: =_xlfn.XLOOKUP(Foundation,Foundationdropdown,OHTerm,"Overhead percentage") -> Administrative expenses | D13: =_xlfn.XLOOKUP(Foundation,Foundationdropdown,OHFoundation,"") -> 0
G14: skjul | H14: skjul
C15: Project title: | K15: =IFERROR("Project length: "& ROUND(ABS(YEARFRAC(startDate,EOMONTH(startDate,12-MONTH(startDate)),1)+YEAR(endDate)-YEAR(startDate)-1+YEARFRAC(endDate,EOMONTH(endDate,-MONTH(endDate)),1)),2) & " years","") -> Project length: 6 years | L15: =IFERROR(IF(DateFormat="Calendar years",L2,"Year 1"),"20XX") -> Year 1 | O15: =IFERROR(IF(DateFormat="Calendar years",O2,"Year 2"),"20XX") -> Year 2 | R15: =IFERROR(IF(DateFormat="Calendar years",R2,"Year 3"),"20XX") -> Year 3 | U15: =IFERROR(IF(DateFormat="Calendar years",U2,"Year 4"),"20XX") -> Year 4 | X15: =IFERROR(IF(DateFormat="Calendar years",X2,"Year 5"),"20XX") -> Year 5 | AA15: =IFERROR(IF(DateFormat="Calendar years",AA2,"Year 6"),"20XX") -> Year 6 | AD15: =IFERROR(IF(DateFormat="Calendar years",AD2,"Year 7"),"20XX") -> Year 7 | AG15: =IFERROR(IF(DateFormat="Calendar years",AG2,"Year 8"),"20XX") -> Year 8 | AJ15: =IFERROR(IF(DateFormat="Calendar years",AJ2,"Year 9"),"20XX") -> Year 9 | AM15: =IFERROR(IF(DateFormat="Calendar years",AM2,"Year 10"),"20XX") -> Year 10 | AP15: TOTAL | AT15: FTE hours
L16: Start | N16: End | O16: Start | Q16: End | R16: Start | T16: End | U16: Start | W16: End | X16: Start | Z16: End | AA16: Start | AC16: End | AD16: Start | AF16: End | AG16: Start | AI16: End | AJ16: Start | AL16: End | AM16: Start | AO16: End | AP16: Start | AR16: End
L17: =IFERROR(IF(DateFormat="Project years",L1,L2),"") -> 46296 | N17: =IFERROR(IF(DateFormat="Project years",N1,N2),"") -> 46660 | O17: =IFERROR(IF(DateFormat="Project years",O1,O2),"") -> 46661 | Q17: =IFERROR(IF(DateFormat="Project years",Q1,Q2),"") -> 47026 | R17: =IFERROR(IF(DateFormat="Project years",R1,R2),"") -> 47027 | T17: =IFERROR(IF(DateFormat="Project years",T1,T2),"") -> 47391 | U17: =IFERROR(IF(DateFormat="Project years",U1,U2),"") -> 47392 | W17: =IFERROR(IF(DateFormat="Project years",W1,W2),"") -> 47756 | X17: =IFERROR(IF(DateFormat="Project years",X1,X2),"") -> 47757 | Z17: =IFERROR(IF(DateFormat="Project years",Z1,Z2),"") -> 48121 | AA17: =IFERROR(IF(DateFormat="Project years",AA1,AA2),"") -> 48122 | AC17: =IFERROR(IF(DateFormat="Project years",AC1,AC2),"") -> 48487 | AD17: =IFERROR(IF(DateFormat="Project years",AD1,AD2),"") | AF17: =IFERROR(IF(DateFormat="Project years",AF1,AF2),"") | AG17: =IFERROR(IF(DateFormat="Project years",AG1,AG2),"") | AI17: =IFERROR(IF(DateFormat="Project years",AI1,AI2),"") | AJ17: =IFERROR(IF(DateFormat="Project years",AJ1,AJ2),"") | AL17: =IFERROR(IF(DateFormat="Project years",AL1,AL2),"") | AM17: =IFERROR(IF(DateFormat="Project years",AM1,AM2),"") | AO17: =IFERROR(IF(DateFormat="Project years",AO1,AO2),"") | AP17: =IF(startDate="","",startDate) -> 46296 | AR17: =IF(endDate="","",endDate) -> 48487
B18: Salary | K18: Project months/year: | L18: =IFERROR(ROUND(IF(MONTH(L17)=MONTH(N17),((YEAR(N17)-YEAR(L17))*12)-12+(12-MONTH(L17))+MONTH(N17)-1+(EOMONTH(L17,0)-L17+1)/DAY(EOMONTH(L17,0))+(1-(EOMONTH(N17,0)-N17)/DAY(EOMONTH(N17,0))),((YEAR(N17)-YEAR(L17))*12)-12+(12-MONTH(L17))+MONTH(N17)-1+(EOMONTH(L17,0)-L17+1)/DAY(EOMONTH(L17,0))+(1-(EOMONTH(N17,0)-N17)/DAY(EOMONTH(N17,0)))),2),0) -> 12 | O18: =IFERROR(ROUND(IF(MONTH(O17)=MONTH(Q17),((YEAR(Q17)-YEAR(O17))*12)-12+(12-MONTH(O17))+MONTH(Q17)-1+(EOMONTH(O17,0)-O17+1)/DAY(EOMONTH(O17,0))+(1-(EOMONTH(Q17,0)-Q17)/DAY(EOMONTH(Q17,0))),((YEAR(Q17)-YEAR(O17))*12)-12+(12-MONTH(O17))+MONTH(Q17)-1+(EOMONTH(O17,0)-O17+1)/DAY(EOMONTH(O17,0))+(1-(EOMONTH(Q17,0)-Q17)/DAY(EOMONTH(Q17,0)))),2),0) -> 12 | R18: =IFERROR(ROUND(IF(MONTH(R17)=MONTH(T17),((YEAR(T17)-YEAR(R17))*12)-12+(12-MONTH(R17))+MONTH(T17)-1+(EOMONTH(R17,0)-R17+1)/DAY(EOMONTH(R17,0))+(1-(EOMONTH(T17,0)-T17)/DAY(EOMONTH(T17,0))),((YEAR(T17)-YEAR(R17))*12)-12+(12-MONTH(R17))+MONTH(T17)-1+(EOMONTH(R17,0)-R17+1)/DAY(EOMONTH(R17,0))+(1-(EOMONTH(T17,0)-T17)/DAY(EOMONTH(T17,0)))),2),0) -> 12 | U18: =IFERROR(ROUND(IF(MONTH(U17)=MONTH(W17),((YEAR(W17)-YEAR(U17))*12)-12+(12-MONTH(U17))+MONTH(W17)-1+(EOMONTH(U17,0)-U17+1)/DAY(EOMONTH(U17,0))+(1-(EOMONTH(W17,0)-W17)/DAY(EOMONTH(W17,0))),((YEAR(W17)-YEAR(U17))*12)-12+(12-MONTH(U17))+MONTH(W17)-1+(EOMONTH(U17,0)-U17+1)/DAY(EOMONTH(U17,0))+(1-(EOMONTH(W17,0)-W17)/DAY(EOMONTH(W17,0)))),2),0) -> 12 | X18: =IFERROR(ROUND(IF(MONTH(X17)=MONTH(Z17),((YEAR(Z17)-YEAR(X17))*12)-12+(12-MONTH(X17))+MONTH(Z17)-1+(EOMONTH(X17,0)-X17+1)/DAY(EOMONTH(X17,0))+(1-(EOMONTH(Z17,0)-Z17)/DAY(EOMONTH(Z17,0))),((YEAR(Z17)-YEAR(X17))*12)-12+(12-MONTH(X17))+MONTH(Z17)-1+(EOMONTH(X17,0)-X17+1)/DAY(EOMONTH(X17,0))+(1-(EOMONTH(Z17,0)-Z17)/DAY(EOMONTH(Z17,0)))),2),0) -> 12 | AA18: =IFERROR(ROUND(IF(MONTH(AA17)=MONTH(AC17),((YEAR(AC17)-YEAR(AA17))*12)-12+(12-MONTH(AA17))+MONTH(AC17)-1+(EOMONTH(AA17,0)-AA17+1)/DAY(EOMONTH(AA17,0))+(1-(EOMONTH(AC17,0)-AC17)/DAY(EOMONTH(AC17,0))),((YEAR(AC17)-YEAR(AA17))*12)-12+(12-MONTH(AA17))+MONTH(AC17)-1+(EOMONTH(AA17,0)-AA17+1)/DAY(EOMONTH(AA17,0))+(1-(EOMONTH(AC17,0)-AC17)/DAY(EOMONTH(AC17,0)))),2),0) -> 12 | AD18: =IFERROR(ROUND(IF(MONTH(AD17)=MONTH(AF17),((YEAR(AF17)-YEAR(AD17))*12)-12+(12-MONTH(AD17))+MONTH(AF17)-1+(EOMONTH(AD17,0)-AD17+1)/DAY(EOMONTH(AD17,0))+(1-(EOMONTH(AF17,0)-AF17)/DAY(EOMONTH(AF17,0))),((YEAR(AF17)-YEAR(AD17))*12)-12+(12-MONTH(AD17))+MONTH(AF17)-1+(EOMONTH(AD17,0)-AD17+1)/DAY(EOMONTH(AD17,0))+(1-(EOMONTH(AF17,0)-AF17)/DAY(EOMONTH(AF17,0)))),2),0) -> 0 | AG18: =IFERROR(ROUND(IF(MONTH(AG17)=MONTH(AI17),((YEAR(AI17)-YEAR(AG17))*12)-12+(12-MONTH(AG17))+MONTH(AI17)-1+(EOMONTH(AG17,0)-AG17+1)/DAY(EOMONTH(AG17,0))+(1-(EOMONTH(AI17,0)-AI17)/DAY(EOMONTH(AI17,0))),((YEAR(AI17)-YEAR(AG17))*12)-12+(12-MONTH(AG17))+MONTH(AI17)-1+(EOMONTH(AG17,0)-AG17+1)/DAY(EOMONTH(AG17,0))+(1-(EOMONTH(AI17,0)-AI17)/DAY(EOMONTH(AI17,0)))),2),0) -> 0 | AJ18: =IFERROR(ROUND(IF(MONTH(AJ17)=MONTH(AL17),((YEAR(AL17)-YEAR(AJ17))*12)-12+(12-MONTH(AJ17))+MONTH(AL17)-1+(EOMONTH(AJ17,0)-AJ17+1)/DAY(EOMONTH(AJ17,0))+(1-(EOMONTH(AL17,0)-AL17)/DAY(EOMONTH(AL17,0))),((YEAR(AL17)-YEAR(AJ17))*12)-12+(12-MONTH(AJ17))+MONTH(AL17)-1+(EOMONTH(AJ17,0)-AJ17+1)/DAY(EOMONTH(AJ17,0))+(1-(EOMONTH(AL17,0)-AL17)/DAY(EOMONTH(AL17,0)))),2),0) -> 0 | AM18: =IFERROR(ROUND(IF(MONTH(AM17)=MONTH(AO17),((YEAR(AO17)-YEAR(AM17))*12)-12+(12-MONTH(AM17))+MONTH(AO17)-1+(EOMONTH(AM17,0)-AM17+1)/DAY(EOMONTH(AM17,0))+(1-(EOMONTH(AO17,0)-AO17)/DAY(EOMONTH(AO17,0))),((YEAR(AO17)-YEAR(AM17))*12)-12+(12-MONTH(AM17))+MONTH(AO17)-1+(EOMONTH(AM17,0)-AM17+1)/DAY(EOMONTH(AM17,0))+(1-(EOMONTH(AO17,0)-AO17)/DAY(EOMONTH(AO17,0)))),2),0) -> 0 | AP18: =IFERROR(ROUND(IF(MONTH(AP17)=MONTH(AR17),((YEAR(AR17)-YEAR(AP17))*12)-12+(12-MONTH(AP17))+MONTH(AR17)-1+(EOMONTH(AP17,0)-AP17+1)/DAY(EOMONTH(AP17,0))+(1-(EOMONTH(AR17,0)-AR17)/DAY(EOMONTH(AR17,0))),((YEAR(AR17)-YEAR(AP17))*12)-12+(12-MONTH(AP17))+MONTH(AR17)-1+(EOMONTH(AP17,0)-AP17+1)/DAY(EOMONTH(AP17,0))+(1-(EOMONTH(AR17,0)-AR17)/DAY(EOMONTH(AR17,0)))),2),"") -> 72 | AT18: 1924
C19: 1. VIP | F19: Notes/Name | G19: Project supplement? | H19: Fraction | I19: Salary/mo 2025 | J19: Hrs/wk | K19: Dept.Serv. | L19: Months | M19: FTE | N19: Costs | O19: Months | P19: FTE | Q19: Costs | R19: Months | S19: FTE | T19: Costs | U19: Months | V19: FTE | W19: Costs | X19: Months | Y19: FTE | Z19: Costs | AA19: Months | AB19: FTE | AC19: Costs | AD19: Months | AE19: FTE | AF19: Costs | AG19: Months | AH19: FTE | AI19: Costs | AJ19: Months | AK19: FTE | AL19: Costs | AM19: Months | AN19: FTE | AO19: Costs | AP19: Months | AQ19: FTE | AR19: Costs | AT19: VIP hours
C20: Postdoc | G20: =_xlfn.XLOOKUP(C20,Lists!$N$3:$N$15,Lists!$O$3:$O$15,"") -> 1 | H20: =J20/37 -> 1 | I20: =_xlfn.XLOOKUP(C20,'AU salary costs 2025'!$B$7:$B$35,'AU salary costs 2025'!$D$7:$D$35, "-") -> 52000 | J20: 37 | L20: 12 | M20: =$H20*(L20/12) -> 1 | N20: =IFERROR($I20*$J20/37*(1+PLPartner1)^N$3*L20,"") -> 662001.6 | O20: 12 | P20: =$H20*(O20/12) -> 1 | Q20: =IFERROR($I20*$J20/37*(1+PLPartner1)^Q$3*O20,"") -> 681861.65 | R20: 12 | S20: =$H20*(R20/12) -> 1 | T20: =IFERROR($I20*$J20/37*(1+PLPartner1)^T$3*R20,"") -> 702317.5 | V20: =$H20*(U20/12) -> 0 | W20: =IFERROR($I20*$J20/37*(1+PLPartner1)^W$3*U20,"") -> 0 | Y20: =$H20*(X20/12) -> 0 | Z20: =IFERROR($I20*$J20/37*(1+PLPartner1)^Z$3*X20,"") -> 0 | AB20: =$H20*(AA20/12) -> 0 | AC20: =IFERROR($I20*$J20/37*(1+PLPartner1)^AC$3*AA20,"") -> 0 | AE20: =$H20*(AD20/12) -> 0 | AF20: =IFERROR($I20*$J20/37*(1+PLPartner1)^AF$3*AD20,"") -> 0 | AH20: =$H20*(AG20/12) -> 0 | AI20: =IFERROR($I20*$J20/37*(1+PLPartner1)^AI$3*AG20,"") -> 0 | AK20: =$H20*(AJ20/12) -> 0 | AL20: =IFERROR($I20*$J20/37*(1+PLPartner1)^AL$3*AJ20,"") -> 0 | AN20: =$H20*(AM20/12) -> 0 | AO20: =IFERROR($I20*$J20/37*(1+PLPartner1)^AO$3*AM20,"") -> 0 | AP20: =SUM(L20,O20,R20,U20,X20,AA20,AD20,AG20,AJ20,AM20) -> 36 | AQ20: =SUM(M20,P20,S20,V20,Y20,AB20,AE20,AH20,AK20,AN20) -> 3 | AR20: =SUM(N20,Q20,T20,W20,Z20,AC20,AF20,AI20,AL20,AO20) -> 2046180.7 | AT20: =AQ20*$AT$18 -> 5772
C21: Postdoc | G21: =_xlfn.XLOOKUP(C21,Lists!$N$3:$N$15,Lists!$O$3:$O$15,"") -> 1 | H21: =J21/37 -> 1 | I21: =_xlfn.XLOOKUP(C21,'AU salary costs 2025'!$B$7:$B$35,'AU salary costs 2025'!$D$7:$D$35, "-") -> 52000 | J21: 37 | M21: =$H21*(L21/12) -> 0 | N21: =IFERROR($I21*$J21/37*(1+PLPartner1)^N$3*L21,"") -> 0 | O21: 12 | P21: =$H21*(O21/12) -> 1 | Q21: =IFERROR($I21*$J21/37*(1+PLPartner1)^Q$3*O21,"") -> 681861.65 | R21: 12 | S21: =$H21*(R21/12) -> 1 | T21: =IFERROR($I21*$J21/37*(1+PLPartner1)^T$3*R21,"") -> 702317.5 | U21: 12 | V21: =$H21*(U21/12) -> 1 | W21: =IFERROR($I21*$J21/37*(1+PLPartner1)^W$3*U21,"") -> 723387.02 | Y21: =$H21*(X21/12) -> 0 | Z21: =IFERROR($I21*$J21/37*(1+PLPartner1)^Z$3*X21,"") -> 0 | AB21: =$H21*(AA21/12) -> 0 | AC21: =IFERROR($I21*$J21/37*(1+PLPartner1)^AC$3*AA21,"") -> 0 | AE21: =$H21*(AD21/12) -> 0 | AF21: =IFERROR($I21*$J21/37*(1+PLPartner1)^AF$3*AD21,"") -> 0 | AH21: =$H21*(AG21/12) -> 0 | AI21: =IFERROR($I21*$J21/37*(1+PLPartner1)^AI$3*AG21,"") -> 0 | AK21: =$H21*(AJ21/12) -> 0 | AL21: =IFERROR($I21*$J21/37*(1+PLPartner1)^AL$3*AJ21,"") -> 0 | AN21: =$H21*(AM21/12) -> 0 | AO21: =IFERROR($I21*$J21/37*(1+PLPartner1)^AO$3*AM21,"") -> 0 | AP21: =SUM(L21,O21,R21,U21,X21,AA21,AD21,AG21,AJ21,AM21) -> 36 | AQ21: =SUM(M21,P21,S21,V21,Y21,AB21,AE21,AH21,AK21,AN21) -> 3 | AR21: =SUM(N21,Q21,T21,W21,Z21,AC21,AF21,AI21,AL21,AO21) -> 2107566.2 | AT21: =AQ21*$AT$18 -> 5772
C22: Postdoc | G22: =_xlfn.XLOOKUP(C22,Lists!$N$3:$N$15,Lists!$O$3:$O$15,"") -> 1 | H22: =J22/37 -> 1 | I22: =_xlfn.XLOOKUP(C22,'AU salary costs 2025'!$B$7:$B$35,'AU salary costs 2025'!$D$7:$D$35, "-") -> 52000 | J22: 37 | M22: =$H22*(L22/12) -> 0 | N22: =IFERROR($I22*$J22/37*(1+PLPartner1)^N$3*L22,"") -> 0 | P22: =$H22*(O22/12) -> 0 | Q22: =IFERROR($I22*$J22/37*(1+PLPartner1)^Q$3*O22,"") -> 0 | R22: 6 | S22: =$H22*(R22/12) -> 0.5 | T22: =IFERROR($I22*$J22/37*(1+PLPartner1)^T$3*R22,"") -> 351158.75 | U22: 12 | V22: =$H22*(U22/12) -> 1 | W22: =IFERROR($I22*$J22/37*(1+PLPartner1)^W$3*U22,"") -> 723387.02 | X22: 12 | Y22: =$H22*(X22/12) -> 1 | Z22: =IFERROR($I22*$J22/37*(1+PLPartner1)^Z$3*X22,"") -> 745088.63 | AA22: 6 | AB22: =$H22*(AA22/12) -> 0.5 | AC22: =IFERROR($I22*$J22/37*(1+PLPartner1)^AC$3*AA22,"") -> 383720.65 | AE22: =$H22*(AD22/12) -> 0 | AF22: =IFERROR($I22*$J22/37*(1+PLPartner1)^AF$3*AD22,"") -> 0 | AH22: =$H22*(AG22/12) -> 0 | AI22: =IFERROR($I22*$J22/37*(1+PLPartner1)^AI$3*AG22,"") -> 0 | AK22: =$H22*(AJ22/12) -> 0 | AL22: =IFERROR($I22*$J22/37*(1+PLPartner1)^AL$3*AJ22,"") -> 0 | AN22: =$H22*(AM22/12) -> 0 | AO22: =IFERROR($I22*$J22/37*(1+PLPartner1)^AO$3*AM22,"") -> 0 | AP22: =SUM(L22,O22,R22,U22,X22,AA22,AD22,AG22,AJ22,AM22) -> 36 | AQ22: =SUM(M22,P22,S22,V22,Y22,AB22,AE22,AH22,AK22,AN22) -> 3 | AR22: =SUM(N22,Q22,T22,W22,Z22,AC22,AF22,AI22,AL22,AO22) -> 2203355.1 | AT22: =AQ22*$AT$18 -> 5772
C23: PhD Student | G23: =_xlfn.XLOOKUP(C23,Lists!$N$3:$N$15,Lists!$O$3:$O$15,"") -> 1 | H23: =J23/37 -> 1 | I23: =_xlfn.XLOOKUP(C23,'AU salary costs 2025'!$B$7:$B$35,'AU salary costs 2025'!$D$7:$D$35, "-") -> 42000 | J23: 37 | L23: 6 | M23: =$H23*(L23/12) -> 0.5 | N23: =IFERROR($I23*$J23/37*(1+PLPartner1)^N$3*L23,"") -> 267346.8 | O23: 12 | P23: =$H23*(O23/12) -> 1 | Q23: =IFERROR($I23*$J23/37*(1+PLPartner1)^Q$3*O23,"") -> 550734.41 | R23: 12 | S23: =$H23*(R23/12) -> 1 | T23: =IFERROR($I23*$J23/37*(1+PLPartner1)^T$3*R23,"") -> 567256.44 | U23: 6 | V23: =$H23*(U23/12) -> 0.5 | W23: =IFERROR($I23*$J23/37*(1+PLPartner1)^W$3*U23,"") -> 292137.07 | Y23: =$H23*(X23/12) -> 0 | Z23: =IFERROR($I23*$J23/37*(1+PLPartner1)^Z$3*X23,"") -> 0 | AB23: =$H23*(AA23/12) -> 0 | AC23: =IFERROR($I23*$J23/37*(1+PLPartner1)^AC$3*AA23,"") -> 0 | AE23: =$H23*(AD23/12) -> 0 | AF23: =IFERROR($I23*$J23/37*(1+PLPartner1)^AF$3*AD23,"") -> 0 | AH23: =$H23*(AG23/12) -> 0 | AI23: =IFERROR($I23*$J23/37*(1+PLPartner1)^AI$3*AG23,"") -> 0 | AK23: =$H23*(AJ23/12) -> 0 | AL23: =IFERROR($I23*$J23/37*(1+PLPartner1)^AL$3*AJ23,"") -> 0 | AN23: =$H23*(AM23/12) -> 0 | AO23: =IFERROR($I23*$J23/37*(1+PLPartner1)^AO$3*AM23,"") -> 0 | AP23: =SUM(L23,O23,R23,U23,X23,AA23,AD23,AG23,AJ23,AM23) -> 36 | AQ23: =SUM(M23,P23,S23,V23,Y23,AB23,AE23,AH23,AK23,AN23) -> 3 | AR23: =SUM(N23,Q23,T23,W23,Z23,AC23,AF23,AI23,AL23,AO23) -> 1677474.7 | AT23: =AQ23*$AT$18 -> 5772
C24: PhD Student | G24: =_xlfn.XLOOKUP(C24,Lists!$N$3:$N$15,Lists!$O$3:$O$15,"") -> 1 | H24: =J24/37 -> 1 | I24: =_xlfn.XLOOKUP(C24,'AU salary costs 2025'!$B$7:$B$35,'AU salary costs 2025'!$D$7:$D$35, "-") -> 42000 | J24: 37 | M24: =$H24*(L24/12) -> 0 | N24: =IFERROR($I24*$J24/37*(1+PLPartner1)^N$3*L24,"") -> 0 | P24: =$H24*(O24/12) -> 0 | Q24: =IFERROR($I24*$J24/37*(1+PLPartner1)^Q$3*O24,"") -> 0 | R24: 6 | S24: =$H24*(R24/12) -> 0.5 | T24: =IFERROR($I24*$J24/37*(1+PLPartner1)^T$3*R24,"") -> 283628.22 | U24: 12 | V24: =$H24*(U24/12) -> 1 | W24: =IFERROR($I24*$J24/37*(1+PLPartner1)^W$3*U24,"") -> 584274.13 | X24: 12 | Y24: =$H24*(X24/12) -> 1 | Z24: =IFERROR($I24*$J24/37*(1+PLPartner1)^Z$3*X24,"") -> 601802.36 | AA24: 6 | AB24: =$H24*(AA24/12) -> 0.5 | AC24: =IFERROR($I24*$J24/37*(1+PLPartner1)^AC$3*AA24,"") -> 309928.21 | AE24: =$H24*(AD24/12) -> 0 | AF24: =IFERROR($I24*$J24/37*(1+PLPartner1)^AF$3*AD24,"") -> 0 | AH24: =$H24*(AG24/12) -> 0 | AI24: =IFERROR($I24*$J24/37*(1+PLPartner1)^AI$3*AG24,"") -> 0 | AK24: =$H24*(AJ24/12) -> 0 | AL24: =IFERROR($I24*$J24/37*(1+PLPartner1)^AL$3*AJ24,"") -> 0 | AN24: =$H24*(AM24/12) -> 0 | AO24: =IFERROR($I24*$J24/37*(1+PLPartner1)^AO$3*AM24,"") -> 0 | AP24: =SUM(L24,O24,R24,U24,X24,AA24,AD24,AG24,AJ24,AM24) -> 36 | AQ24: =SUM(M24,P24,S24,V24,Y24,AB24,AE24,AH24,AK24,AN24) -> 3 | AR24: =SUM(N24,Q24,T24,W24,Z24,AC24,AF24,AI24,AL24,AO24) -> 1779632.9 | AT24: =AQ24*$AT$18 -> 5772
C25: - | G25: =_xlfn.XLOOKUP(C25,Lists!$N$3:$N$15,Lists!$O$3:$O$15,"") | H25: =J25/37 -> 1 | I25: =_xlfn.XLOOKUP(C25,'AU salary costs 2025'!$B$7:$B$35,'AU salary costs 2025'!$D$7:$D$35, "-") -> - | J25: 37 | M25: =$H25*(L25/12) -> 0 | N25: =IFERROR($I25*$J25/37*(1+PLPartner1)^N$3*L25,"") | P25: =$H25*(O25/12) -> 0 | Q25: =IFERROR($I25*$J25/37*(1+PLPartner1)^Q$3*O25,"") | S25: =$H25*(R25/12) -> 0 | T25: =IFERROR($I25*$J25/37*(1+PLPartner1)^T$3*R25,"") | V25: =$H25*(U25/12) -> 0 | W25: =IFERROR($I25*$J25/37*(1+PLPartner1)^W$3*U25,"") | Y25: =$H25*(X25/12) -> 0 | Z25: =IFERROR($I25*$J25/37*(1+PLPartner1)^Z$3*X25,"") | AB25: =$H25*(AA25/12) -> 0 | AC25: =IFERROR($I25*$J25/37*(1+PLPartner1)^AC$3*AA25,"") | AE25: =$H25*(AD25/12) -> 0 | AF25: =IFERROR($I25*$J25/37*(1+PLPartner1)^AF$3*AD25,"") | AH25: =$H25*(AG25/12) -> 0 | AI25: =IFERROR($I25*$J25/37*(1+PLPartner1)^AI$3*AG25,"") | AK25: =$H25*(AJ25/12) -> 0 | AL25: =IFERROR($I25*$J25/37*(1+PLPartner1)^AL$3*AJ25,"") | AN25: =$H25*(AM25/12) -> 0 | AO25: =IFERROR($I25*$J25/37*(1+PLPartner1)^AO$3*AM25,"") | AP25: =SUM(L25,O25,R25,U25,X25,AA25,AD25,AG25,AJ25,AM25) -> 0 | AQ25: =SUM(M25,P25,S25,V25,Y25,AB25,AE25,AH25,AK25,AN25) -> 0 | AR25: =SUM(N25,Q25,T25,W25,Z25,AC25,AF25,AI25,AL25,AO25) -> 0 | AT25: =AQ25*$AT$18 -> 0
C26: - | G26: =_xlfn.XLOOKUP(C26,Lists!$N$3:$N$15,Lists!$O$3:$O$15,"") | H26: =J26/37 -> 1 | I26: =_xlfn.XLOOKUP(C26,'AU salary costs 2025'!$B$7:$B$35,'AU salary costs 2025'!$D$7:$D$35, "-") -> - | J26: 37 | M26: =$H26*(L26/12) -> 0 | N26: =IFERROR($I26*$J26/37*(1+PLPartner1)^N$3*L26,"") | P26: =$H26*(O26/12) -> 0 | Q26: =IFERROR($I26*$J26/37*(1+PLPartner1)^Q$3*O26,"") | S26: =$H26*(R26/12) -> 0 | T26: =IFERROR($I26*$J26/37*(1+PLPartner1)^T$3*R26,"") | V26: =$H26*(U26/12) -> 0 | W26: =IFERROR($I26*$J26/37*(1+PLPartner1)^W$3*U26,"") | Y26: =$H26*(X26/12) -> 0 | Z26: =IFERROR($I26*$J26/37*(1+PLPartner1)^Z$3*X26,"") | AB26: =$H26*(AA26/12) -> 0 | AC26: =IFERROR($I26*$J26/37*(1+PLPartner1)^AC$3*AA26,"") | AE26: =$H26*(AD26/12) -> 0 | AF26: =IFERROR($I26*$J26/37*(1+PLPartner1)^AF$3*AD26,"") | AH26: =$H26*(AG26/12) -> 0 | AI26: =IFERROR($I26*$J26/37*(1+PLPartner1)^AI$3*AG26,"") | AK26: =$H26*(AJ26/12) -> 0 | AL26: =IFERROR($I26*$J26/37*(1+PLPartner1)^AL$3*AJ26,"") | AN26: =$H26*(AM26/12) -> 0 | AO26: =IFERROR($I26*$J26/37*(1+PLPartner1)^AO$3*AM26,"") | AP26: =SUM(L26,O26,R26,U26,X26,AA26,AD26,AG26,AJ26,AM26) -> 0 | AQ26: =SUM(M26,P26,S26,V26,Y26,AB26,AE26,AH26,AK26,AN26) -> 0 | AR26: =SUM(N26,Q26,T26,W26,Z26,AC26,AF26,AI26,AL26,AO26) -> 0 | AT26: =AQ26*$AT$18 -> 0
C27: - | G27: =_xlfn.XLOOKUP(C27,Lists!$N$3:$N$15,Lists!$O$3:$O$15,"") | H27: =J27/37 -> 1 | I27: =_xlfn.XLOOKUP(C27,'AU salary costs 2025'!$B$7:$B$35,'AU salary costs 2025'!$D$7:$D$35, "-") -> - | J27: 37 | M27: =$H27*(L27/12) -> 0 | N27: =IFERROR($I27*$J27/37*(1+PLPartner1)^N$3*L27,"") | P27: =$H27*(O27/12) -> 0 | Q27: =IFERROR($I27*$J27/37*(1+PLPartner1)^Q$3*O27,"") | S27: =$H27*(R27/12) -> 0 | T27: =IFERROR($I27*$J27/37*(1+PLPartner1)^T$3*R27,"") | V27: =$H27*(U27/12) -> 0 | W27: =IFERROR($I27*$J27/37*(1+PLPartner1)^W$3*U27,"") | Y27: =$H27*(X27/12) -> 0 | Z27: =IFERROR($I27*$J27/37*(1+PLPartner1)^Z$3*X27,"") | AB27: =$H27*(AA27/12) -> 0 | AC27: =IFERROR($I27*$J27/37*(1+PLPartner1)^AC$3*AA27,"") | AE27: =$H27*(AD27/12) -> 0 | AF27: =IFERROR($I27*$J27/37*(1+PLPartner1)^AF$3*AD27,"") | AH27: =$H27*(AG27/12) -> 0 | AI27: =IFERROR($I27*$J27/37*(1+PLPartner1)^AI$3*AG27,"") | AK27: =$H27*(AJ27/12) -> 0 | AL27: =IFERROR($I27*$J27/37*(1+PLPartner1)^AL$3*AJ27,"") | AN27: =$H27*(AM27/12) -> 0 | AO27: =IFERROR($I27*$J27/37*(1+PLPartner1)^AO$3*AM27,"") | AP27: =SUM(L27,O27,R27,U27,X27,AA27,AD27,AG27,AJ27,AM27) -> 0 | AQ27: =SUM(M27,P27,S27,V27,Y27,AB27,AE27,AH27,AK27,AN27) -> 0 | AR27: =SUM(N27,Q27,T27,W27,Z27,AC27,AF27,AI27,AL27,AO27) -> 0 | AT27: =AQ27*$AT$18 -> 0
C28: - | G28: =_xlfn.XLOOKUP(C28,Lists!$N$3:$N$15,Lists!$O$3:$O$15,"") | H28: =J28/37 -> 1 | I28: =_xlfn.XLOOKUP(C28,'AU salary costs 2025'!$B$7:$B$35,'AU salary costs 2025'!$D$7:$D$35, "-") -> - | J28: 37 | M28: =$H28*(L28/12) -> 0 | N28: =IFERROR($I28*$J28/37*(1+PLPartner1)^N$3*L28,"") | P28: =$H28*(O28/12) -> 0 | Q28: =IFERROR($I28*$J28/37*(1+PLPartner1)^Q$3*O28,"") | S28: =$H28*(R28/12) -> 0 | T28: =IFERROR($I28*$J28/37*(1+PLPartner1)^T$3*R28,"") | V28: =$H28*(U28/12) -> 0 | W28: =IFERROR($I28*$J28/37*(1+PLPartner1)^W$3*U28,"") | Y28: =$H28*(X28/12) -> 0 | Z28: =IFERROR($I28*$J28/37*(1+PLPartner1)^Z$3*X28,"") | AB28: =$H28*(AA28/12) -> 0 | AC28: =IFERROR($I28*$J28/37*(1+PLPartner1)^AC$3*AA28,"") | AE28: =$H28*(AD28/12) -> 0 | AF28: =IFERROR($I28*$J28/37*(1+PLPartner1)^AF$3*AD28,"") | AH28: =$H28*(AG28/12) -> 0 | AI28: =IFERROR($I28*$J28/37*(1+PLPartner1)^AI$3*AG28,"") | AK28: =$H28*(AJ28/12) -> 0 | AL28: =IFERROR($I28*$J28/37*(1+PLPartner1)^AL$3*AJ28,"") | AN28: =$H28*(AM28/12) -> 0 | AO28: =IFERROR($I28*$J28/37*(1+PLPartner1)^AO$3*AM28,"") | AP28: =SUM(L28,O28,R28,U28,X28,AA28,AD28,AG28,AJ28,AM28) -> 0 | AQ28: =SUM(M28,P28,S28,V28,Y28,AB28,AE28,AH28,AK28,AN28) -> 0 | AR28: =SUM(N28,Q28,T28,W28,Z28,AC28,AF28,AI28,AL28,AO28) -> 0 | AT28: =AQ28*$AT$18 -> 0
C29: - | G29: =_xlfn.XLOOKUP(C29,Lists!$N$3:$N$15,Lists!$O$3:$O$15,"") | H29: =J29/37 -> 1 | I29: =_xlfn.XLOOKUP(C29,'AU salary costs 2025'!$B$7:$B$35,'AU salary costs 2025'!$D$7:$D$35, "-") -> - | J29: 37 | M29: =$H29*(L29/12) -> 0 | N29: =IFERROR($I29*$J29/37*(1+PLPartner1)^N$3*L29,"") | P29: =$H29*(O29/12) -> 0 | Q29: =IFERROR($I29*$J29/37*(1+PLPartner1)^Q$3*O29,"") | S29: =$H29*(R29/12) -> 0 | T29: =IFERROR($I29*$J29/37*(1+PLPartner1)^T$3*R29,"") | V29: =$H29*(U29/12) -> 0 | W29: =IFERROR($I29*$J29/37*(1+PLPartner1)^W$3*U29,"") | Y29: =$H29*(X29/12) -> 0 | Z29: =IFERROR($I29*$J29/37*(1+PLPartner1)^Z$3*X29,"") | AB29: =$H29*(AA29/12) -> 0 | AC29: =IFERROR($I29*$J29/37*(1+PLPartner1)^AC$3*AA29,"") | AE29: =$H29*(AD29/12) -> 0 | AF29: =IFERROR($I29*$J29/37*(1+PLPartner1)^AF$3*AD29,"") | AH29: =$H29*(AG29/12) -> 0 | AI29: =IFERROR($I29*$J29/37*(1+PLPartner1)^AI$3*AG29,"") | AK29: =$H29*(AJ29/12) -> 0 | AL29: =IFERROR($I29*$J29/37*(1+PLPartner1)^AL$3*AJ29,"") | AN29: =$H29*(AM29/12) -> 0 | AO29: =IFERROR($I29*$J29/37*(1+PLPartner1)^AO$3*AM29,"") | AP29: =SUM(L29,O29,R29,U29,X29,AA29,AD29,AG29,AJ29,AM29) -> 0 | AQ29: =SUM(M29,P29,S29,V29,Y29,AB29,AE29,AH29,AK29,AN29) -> 0 | AR29: =SUM(N29,Q29,T29,W29,Z29,AC29,AF29,AI29,AL29,AO29) -> 0 | AT29: =AQ29*$AT$18 -> 0
C30: - | G30: =_xlfn.XLOOKUP(C30,Lists!$N$3:$N$15,Lists!$O$3:$O$15,"") | H30: =J30/37 -> 1 | I30: =_xlfn.XLOOKUP(C30,'AU salary costs 2025'!$B$7:$B$35,'AU salary costs 2025'!$D$7:$D$35, "-") -> - | J30: 37 | M30: =$H30*(L30/12) -> 0 | N30: =IFERROR($I30*$J30/37*(1+PLPartner1)^N$3*L30,"") | P30: =$H30*(O30/12) -> 0 | Q30: =IFERROR($I30*$J30/37*(1+PLPartner1)^Q$3*O30,"") | S30: =$H30*(R30/12) -> 0 | T30: =IFERROR($I30*$J30/37*(1+PLPartner1)^T$3*R30,"") | V30: =$H30*(U30/12) -> 0 | W30: =IFERROR($I30*$J30/37*(1+PLPartner1)^W$3*U30,"") | Y30: =$H30*(X30/12) -> 0 | Z30: =IFERROR($I30*$J30/37*(1+PLPartner1)^Z$3*X30,"") | AB30: =$H30*(AA30/12) -> 0 | AC30: =IFERROR($I30*$J30/37*(1+PLPartner1)^AC$3*AA30,"") | AE30: =$H30*(AD30/12) -> 0 | AF30: =IFERROR($I30*$J30/37*(1+PLPartner1)^AF$3*AD30,"") | AH30: =$H30*(AG30/12) -> 0 | AI30: =IFERROR($I30*$J30/37*(1+PLPartner1)^AI$3*AG30,"") | AK30: =$H30*(AJ30/12) -> 0 | AL30: =IFERROR($I30*$J30/37*(1+PLPartner1)^AL$3*AJ30,"") | AN30: =$H30*(AM30/12) -> 0 | AO30: =IFERROR($I30*$J30/37*(1+PLPartner1)^AO$3*AM30,"") | AP30: =SUM(L30,O30,R30,U30,X30,AA30,AD30,AG30,AJ30,AM30) -> 0 | AQ30: =SUM(M30,P30,S30,V30,Y30,AB30,AE30,AH30,AK30,AN30) -> 0 | AR30: =SUM(N30,Q30,T30,W30,Z30,AC30,AF30,AI30,AL30,AO30) -> 0 | AT30: =AQ30*$AT$18 -> 0
C31: - | G31: =_xlfn.XLOOKUP(C31,Lists!$N$3:$N$15,Lists!$O$3:$O$15,"") | H31: =J31/37 -> 1 | I31: =_xlfn.XLOOKUP(C31,'AU salary costs 2025'!$B$7:$B$35,'AU salary costs 2025'!$D$7:$D$35, "-") -> - | J31: 37 | M31: =$H31*(L31/12) -> 0 | N31: =IFERROR($I31*$J31/37*(1+PLPartner1)^N$3*L31,"") | P31: =$H31*(O31/12) -> 0 | Q31: =IFERROR($I31*$J31/37*(1+PLPartner1)^Q$3*O31,"") | S31: =$H31*(R31/12) -> 0 | T31: =IFERROR($I31*$J31/37*(1+PLPartner1)^T$3*R31,"") | V31: =$H31*(U31/12) -> 0 | W31: =IFERROR($I31*$J31/37*(1+PLPartner1)^W$3*U31,"") | Y31: =$H31*(X31/12) -> 0 | Z31: =IFERROR($I31*$J31/37*(1+PLPartner1)^Z$3*X31,"") | AB31: =$H31*(AA31/12) -> 0 | AC31: =IFERROR($I31*$J31/37*(1+PLPartner1)^AC$3*AA31,"") | AE31: =$H31*(AD31/12) -> 0 | AF31: =IFERROR($I31*$J31/37*(1+PLPartner1)^AF$3*AD31,"") | AH31: =$H31*(AG31/12) -> 0 | AI31: =IFERROR($I31*$J31/37*(1+PLPartner1)^AI$3*AG31,"") | AK31: =$H31*(AJ31/12) -> 0 | AL31: =IFERROR($I31*$J31/37*(1+PLPartner1)^AL$3*AJ31,"") | AN31: =$H31*(AM31/12) -> 0 | AO31: =IFERROR($I31*$J31/37*(1+PLPartner1)^AO$3*AM31,"") | AP31: =SUM(L31,O31,R31,U31,X31,AA31,AD31,AG31,AJ31,AM31) -> 0 | AQ31: =SUM(M31,P31,S31,V31,Y31,AB31,AE31,AH31,AK31,AN31) -> 0 | AR31: =SUM(N31,Q31,T31,W31,Z31,AC31,AF31,AI31,AL31,AO31) -> 0 | AT31: =AQ31*$AT$18 -> 0
C32: - | G32: =_xlfn.XLOOKUP(C32,Lists!$N$3:$N$15,Lists!$O$3:$O$15,"") | H32: =J32/37 -> 1 | I32: =_xlfn.XLOOKUP(C32,'AU salary costs 2025'!$B$7:$B$35,'AU salary costs 2025'!$D$7:$D$35, "-") -> - | J32: 37 | M32: =$H32*(L32/12) -> 0 | N32: =IFERROR($I32*$J32/37*(1+PLPartner1)^N$3*L32,"") | P32: =$H32*(O32/12) -> 0 | Q32: =IFERROR($I32*$J32/37*(1+PLPartner1)^Q$3*O32,"") | S32: =$H32*(R32/12) -> 0 | T32: =IFERROR($I32*$J32/37*(1+PLPartner1)^T$3*R32,"") | V32: =$H32*(U32/12) -> 0 | W32: =IFERROR($I32*$J32/37*(1+PLPartner1)^W$3*U32,"") | Y32: =$H32*(X32/12) -> 0 | Z32: =IFERROR($I32*$J32/37*(1+PLPartner1)^Z$3*X32,"") | AB32: =$H32*(AA32/12) -> 0 | AC32: =IFERROR($I32*$J32/37*(1+PLPartner1)^AC$3*AA32,"") | AE32: =$H32*(AD32/12) -> 0 | AF32: =IFERROR($I32*$J32/37*(1+PLPartner1)^AF$3*AD32,"") | AH32: =$H32*(AG32/12) -> 0 | AI32: =IFERROR($I32*$J32/37*(1+PLPartner1)^AI$3*AG32,"") | AK32: =$H32*(AJ32/12) -> 0 | AL32: =IFERROR($I32*$J32/37*(1+PLPartner1)^AL$3*AJ32,"") | AN32: =$H32*(AM32/12) -> 0 | AO32: =IFERROR($I32*$J32/37*(1+PLPartner1)^AO$3*AM32,"") | AP32: =SUM(L32,O32,R32,U32,X32,AA32,AD32,AG32,AJ32,AM32) -> 0 | AQ32: =SUM(M32,P32,S32,V32,Y32,AB32,AE32,AH32,AK32,AN32) -> 0 | AR32: =SUM(N32,Q32,T32,W32,Z32,AC32,AF32,AI32,AL32,AO32) -> 0 | AT32: =AQ32*$AT$18 -> 0
C33: - | G33: =_xlfn.XLOOKUP(C33,Lists!$N$3:$N$15,Lists!$O$3:$O$15,"") | H33: =J33/37 -> 1 | I33: =_xlfn.XLOOKUP(C33,'AU salary costs 2025'!$B$7:$B$35,'AU salary costs 2025'!$D$7:$D$35, "-") -> - | J33: 37 | M33: =$H33*(L33/12) -> 0 | N33: =IFERROR($I33*$J33/37*(1+PLPartner1)^N$3*L33,"") | P33: =$H33*(O33/12) -> 0 | Q33: =IFERROR($I33*$J33/37*(1+PLPartner1)^Q$3*O33,"") | S33: =$H33*(R33/12) -> 0 | T33: =IFERROR($I33*$J33/37*(1+PLPartner1)^T$3*R33,"") | V33: =$H33*(U33/12) -> 0 | W33: =IFERROR($I33*$J33/37*(1+PLPartner1)^W$3*U33,"") | Y33: =$H33*(X33/12) -> 0 | Z33: =IFERROR($I33*$J33/37*(1+PLPartner1)^Z$3*X33,"") | AB33: =$H33*(AA33/12) -> 0 | AC33: =IFERROR($I33*$J33/37*(1+PLPartner1)^AC$3*AA33,"") | AE33: =$H33*(AD33/12) -> 0 | AF33: =IFERROR($I33*$J33/37*(1+PLPartner1)^AF$3*AD33,"") | AH33: =$H33*(AG33/12) -> 0 | AI33: =IFERROR($I33*$J33/37*(1+PLPartner1)^AI$3*AG33,"") | AK33: =$H33*(AJ33/12) -> 0 | AL33: =IFERROR($I33*$J33/37*(1+PLPartner1)^AL$3*AJ33,"") | AN33: =$H33*(AM33/12) -> 0 | AO33: =IFERROR($I33*$J33/37*(1+PLPartner1)^AO$3*AM33,"") | AP33: =SUM(L33,O33,R33,U33,X33,AA33,AD33,AG33,AJ33,AM33) -> 0 | AQ33: =SUM(M33,P33,S33,V33,Y33,AB33,AE33,AH33,AK33,AN33) -> 0 | AR33: =SUM(N33,Q33,T33,W33,Z33,AC33,AF33,AI33,AL33,AO33) -> 0 | AT33: =AQ33*$AT$18 -> 0
C34: - | G34: =_xlfn.XLOOKUP(C34,Lists!$N$3:$N$15,Lists!$O$3:$O$15,"") | H34: =J34/37 -> 1 | I34: =_xlfn.XLOOKUP(C34,'AU salary costs 2025'!$B$7:$B$35,'AU salary costs 2025'!$D$7:$D$35, "-") -> - | J34: 37 | M34: =$H34*(L34/12) -> 0 | N34: =IFERROR($I34*$J34/37*(1+PLPartner1)^N$3*L34,"") | P34: =$H34*(O34/12) -> 0 | Q34: =IFERROR($I34*$J34/37*(1+PLPartner1)^Q$3*O34,"") | S34: =$H34*(R34/12) -> 0 | T34: =IFERROR($I34*$J34/37*(1+PLPartner1)^T$3*R34,"") | V34: =$H34*(U34/12) -> 0 | W34: =IFERROR($I34*$J34/37*(1+PLPartner1)^W$3*U34,"") | Y34: =$H34*(X34/12) -> 0 | Z34: =IFERROR($I34*$J34/37*(1+PLPartner1)^Z$3*X34,"") | AB34: =$H34*(AA34/12) -> 0 | AC34: =IFERROR($I34*$J34/37*(1+PLPartner1)^AC$3*AA34,"") | AE34: =$H34*(AD34/12) -> 0 | AF34: =IFERROR($I34*$J34/37*(1+PLPartner1)^AF$3*AD34,"") | AH34: =$H34*(AG34/12) -> 0 | AI34: =IFERROR($I34*$J34/37*(1+PLPartner1)^AI$3*AG34,"") | AK34: =$H34*(AJ34/12) -> 0 | AL34: =IFERROR($I34*$J34/37*(1+PLPartner1)^AL$3*AJ34,"") | AN34: =$H34*(AM34/12) -> 0 | AO34: =IFERROR($I34*$J34/37*(1+PLPartner1)^AO$3*AM34,"") | AP34: =SUM(L34,O34,R34,U34,X34,AA34,AD34,AG34,AJ34,AM34) -> 0 | AQ34: =SUM(M34,P34,S34,V34,Y34,AB34,AE34,AH34,AK34,AN34) -> 0 | AR34: =SUM(N34,Q34,T34,W34,Z34,AC34,AF34,AI34,AL34,AO34) -> 0 | AT34: =AQ34*$AT$18 -> 0
C35: - | G35: =_xlfn.XLOOKUP(C35,Lists!$N$3:$N$15,Lists!$O$3:$O$15,"") | H35: =J35/37 -> 1 | I35: =_xlfn.XLOOKUP(C35,'AU salary costs 2025'!$B$7:$B$35,'AU salary costs 2025'!$D$7:$D$35, "-") -> - | J35: 37 | M35: =$H35*(L35/12) -> 0 | N35: =IFERROR($I35*$J35/37*(1+PLPartner1)^N$3*L35,"") | P35: =$H35*(O35/12) -> 0 | Q35: =IFERROR($I35*$J35/37*(1+PLPartner1)^Q$3*O35,"") | S35: =$H35*(R35/12) -> 0 | T35: =IFERROR($I35*$J35/37*(1+PLPartner1)^T$3*R35,"") | V35: =$H35*(U35/12) -> 0 | W35: =IFERROR($I35*$J35/37*(1+PLPartner1)^W$3*U35,"") | Y35: =$H35*(X35/12) -> 0 | Z35: =IFERROR($I35*$J35/37*(1+PLPartner1)^Z$3*X35,"") | AB35: =$H35*(AA35/12) -> 0 | AC35: =IFERROR($I35*$J35/37*(1+PLPartner1)^AC$3*AA35,"") | AE35: =$H35*(AD35/12) -> 0 | AF35: =IFERROR($I35*$J35/37*(1+PLPartner1)^AF$3*AD35,"") | AH35: =$H35*(AG35/12) -> 0 | AI35: =IFERROR($I35*$J35/37*(1+PLPartner1)^AI$3*AG35,"") | AK35: =$H35*(AJ35/12) -> 0 | AL35: =IFERROR($I35*$J35/37*(1+PLPartner1)^AL$3*AJ35,"") | AN35: =$H35*(AM35/12) -> 0 | AO35: =IFERROR($I35*$J35/37*(1+PLPartner1)^AO$3*AM35,"") | AP35: =SUM(L35,O35,R35,U35,X35,AA35,AD35,AG35,AJ35,AM35) -> 0 | AQ35: =SUM(M35,P35,S35,V35,Y35,AB35,AE35,AH35,AK35,AN35) -> 0 | AR35: =SUM(N35,Q35,T35,W35,Z35,AC35,AF35,AI35,AL35,AO35) -> 0 | AT35: =AQ35*$AT$18 -> 0
B36: A | K36: Subtotal | L36: =SUM(L20:L35) -> 18 | M36: =SUM(M20:M35) -> 1.5 | N36: =SUM(N20:N35) -> 929348.4 | O36: =SUM(O20:O35) -> 36 | P36: =SUM(P20:P35) -> 3 | Q36: =SUM(Q20:Q35) -> 1914457.7 | R36: =SUM(R20:R35) -> 48 | S36: =SUM(S20:S35) -> 4 | ... AR36: =SUM(AR20:AR35) -> 9814209.6 | AT36: =AQ36*$AT$18 -> 28860
C37: 1. VIP Co-financing | F37: =F19 -> Notes/Name | I37: =I19 -> Salary/mo 2025 | J37: =J19 -> Hrs/wk | AT37: Co-financed VIP hours
C38: - | H38: =J38/37 -> 1 | I38: =_xlfn.XLOOKUP(C38,'AU salary costs 2025'!$B$7:$B$35,'AU salary costs 2025'!$D$7:$D$35, "-") -> - | J38: 37 | M38: =$H38*(L38/12) -> 0 | N38: =IFERROR($I38*$J38/37*(1+PLPartner1)^N$3*L38,"") | P38: =$H38*(O38/12) -> 0 | Q38: =IFERROR($I38*$J38/37*(1+PLPartner1)^Q$3*O38,"") | S38: =$H38*(R38/12) -> 0 | T38: =IFERROR($I38*$J38/37*(1+PLPartner1)^T$3*R38,"") | V38: =$H38*(U38/12) -> 0 | W38: =IFERROR($I38*$J38/37*(1+PLPartner1)^W$3*U38,"") | Y38: =$H38*(X38/12) -> 0 | Z38: =IFERROR($I38*$J38/37*(1+PLPartner1)^Z$3*X38,"") | AB38: =$H38*(AA38/12) -> 0 | AC38: =IFERROR($I38*$J38/37*(1+PLPartner1)^AC$3*AA38,"") | AE38: =$H38*(AD38/12) -> 0 | AF38: =IFERROR($I38*$J38/37*(1+PLPartner1)^AF$3*AD38,"") | AH38: =$H38*(AG38/12) -> 0 | AI38: =IFERROR($I38*$J38/37*(1+PLPartner1)^AI$3*AG38,"") | AK38: =$H38*(AJ38/12) -> 0 | AL38: =IFERROR($I38*$J38/37*(1+PLPartner1)^AL$3*AJ38,"") | AN38: =$H38*(AM38/12) -> 0 | AO38: =IFERROR($I38*$J38/37*(1+PLPartner1)^AO$3*AM38,"") | AP38: =SUM(L38,O38,R38,U38,X38,AA38,AD38,AG38,AJ38,AM38) -> 0 | AQ38: =SUM(M38,P38,S38,V38,Y38,AB38,AE38,AH38,AK38,AN38) -> 0 | AR38: =SUM(N38,Q38,T38,W38,Z38,AC38,AF38,AI38,AL38,AO38) -> 0 | AT38: =AQ38*$AT$18 -> 0
C39: - | H39: =J39/37 -> 1 | I39: =_xlfn.XLOOKUP(C39,'AU salary costs 2025'!$B$7:$B$35,'AU salary costs 2025'!$D$7:$D$35, "-") -> - | J39: 37 | M39: =$H39*(L39/12) -> 0 | N39: =IFERROR($I39*$J39/37*(1+PLPartner1)^N$3*L39,"") | P39: =$H39*(O39/12) -> 0 | Q39: =IFERROR($I39*$J39/37*(1+PLPartner1)^Q$3*O39,"") | S39: =$H39*(R39/12) -> 0 | T39: =IFERROR($I39*$J39/37*(1+PLPartner1)^T$3*R39,"") | V39: =$H39*(U39/12) -> 0 | W39: =IFERROR($I39*$J39/37*(1+PLPartner1)^W$3*U39,"") | Y39: =$H39*(X39/12) -> 0 | Z39: =IFERROR($I39*$J39/37*(1+PLPartner1)^Z$3*X39,"") | AB39: =$H39*(AA39/12) -> 0 | AC39: =IFERROR($I39*$J39/37*(1+PLPartner1)^AC$3*AA39,"") | AE39: =$H39*(AD39/12) -> 0 | AF39: =IFERROR($I39*$J39/37*(1+PLPartner1)^AF$3*AD39,"") | AH39: =$H39*(AG39/12) -> 0 | AI39: =IFERROR($I39*$J39/37*(1+PLPartner1)^AI$3*AG39,"") | AK39: =$H39*(AJ39/12) -> 0 | AL39: =IFERROR($I39*$J39/37*(1+PLPartner1)^AL$3*AJ39,"") | AN39: =$H39*(AM39/12) -> 0 | AO39: =IFERROR($I39*$J39/37*(1+PLPartner1)^AO$3*AM39,"") | AP39: =SUM(L39,O39,R39,U39,X39,AA39,AD39,AG39,AJ39,AM39) -> 0 | AQ39: =SUM(M39,P39,S39,V39,Y39,AB39,AE39,AH39,AK39,AN39) -> 0 | AR39: =SUM(N39,Q39,T39,W39,Z39,AC39,AF39,AI39,AL39,AO39) -> 0 | AT39: =AQ39*$AT$18 -> 0
C40: - | H40: =J40/37 -> 1 | I40: =_xlfn.XLOOKUP(C40,'AU salary costs 2025'!$B$7:$B$35,'AU salary costs 2025'!$D$7:$D$35, "-") -> - | J40: 37 | M40: =$H40*(L40/12) -> 0 | N40: =IFERROR($I40*$J40/37*(1+PLPartner1)^N$3*L40,"") | P40: =$H40*(O40/12) -> 0 | Q40: =IFERROR($I40*$J40/37*(1+PLPartner1)^Q$3*O40,"") | S40: =$H40*(R40/12) -> 0 | T40: =IFERROR($I40*$J40/37*(1+PLPartner1)^T$3*R40,"") | V40: =$H40*(U40/12) -> 0 | W40: =IFERROR($I40*$J40/37*(1+PLPartner1)^W$3*U40,"") | Y40: =$H40*(X40/12) -> 0 | Z40: =IFERROR($I40*$J40/37*(1+PLPartner1)^Z$3*X40,"") | AB40: =$H40*(AA40/12) -> 0 | AC40: =IFERROR($I40*$J40/37*(1+PLPartner1)^AC$3*AA40,"") | AE40: =$H40*(AD40/12) -> 0 | AF40: =IFERROR($I40*$J40/37*(1+PLPartner1)^AF$3*AD40,"") | AH40: =$H40*(AG40/12) -> 0 | AI40: =IFERROR($I40*$J40/37*(1+PLPartner1)^AI$3*AG40,"") | AK40: =$H40*(AJ40/12) -> 0 | AL40: =IFERROR($I40*$J40/37*(1+PLPartner1)^AL$3*AJ40,"") | AN40: =$H40*(AM40/12) -> 0 | AO40: =IFERROR($I40*$J40/37*(1+PLPartner1)^AO$3*AM40,"") | AP40: =SUM(L40,O40,R40,U40,X40,AA40,AD40,AG40,AJ40,AM40) -> 0 | AQ40: =SUM(M40,P40,S40,V40,Y40,AB40,AE40,AH40,AK40,AN40) -> 0 | AR40: =SUM(N40,Q40,T40,W40,Z40,AC40,AF40,AI40,AL40,AO40) -> 0 | AT40: =AQ40*$AT$18 -> 0
...

Sheet ReAp
H17: =YEARFRAC(AU!$L$17,IF(YEAR(AU!$N$17)=YEAR(AU!$L$1),AU!$N$17,DATE(YEAR(AU!$L$1),12,31)))*12 -> 3
H18: =AU!L18-H17 -> 9
H19: =SUM(H17:H18) -> 12

Sheet Overview - AU
B1: Applied for from the foundation | Q1: Co-financing
B3: =AU!C19 & " Man months" -> 1. VIP Man months | D3: =AU!L15 -> Year 1 | E3: =AU!O15 -> Year 2 | F3: =AU!R15 -> Year 3 | G3: =AU!U15 -> Year 4 | H3: =AU!X15 -> Year 5 | I3: =AU!AA15 -> Year 6 | J3: =AU!AD15 -> Year 7 | K3: =AU!AG15 -> Year 8 | L3: =AU!AJ15 -> Year 9 | M3: =AU!AM15 -> Year 10 | N3: Total | Q3: =B3 -> 1. VIP Man months | S3: =AU!L15 -> Year 1 | T3: =AU!O15 -> Year 2 | U3: =AU!R15 -> Year 3 | V3: =AU!U15 -> Year 4 | W3: =AU!X15 -> Year 5 | X3: =AU!AA15 -> Year 6 | Y3: =AU!AD15 -> Year 7 | Z3: =AU!AG15 -> Year 8 | AA3: =AU!AJ15 -> Year 9 | AB3: =AU!AM15 -> Year 10 | AC3: Total
B4: =AU!C20 -> Postdoc | C4: =IF(AU!F20=0,"",AU!F20) | D4: =AU!L20 -> 12 | E4: =AU!O20 -> 12 | F4: =AU!R20 -> 12 | G4: =AU!U20 -> 0 | H4: =AU!X20 -> 0 | I4: =AU!AA20 -> 0 | J4: =AU!AD20 -> 0 | K4: =AU!AG20 -> 0 | L4: =AU!AJ20 -> 0 | M4: =AU!AM20 -> 0 | N4: =SUM(D4:M4) -> 36 | Q4: =AU!C38 -> - | R4: =IF(AU!F38=0,"",AU!F38) | S4: =AU!L38 -> 0 | T4: =AU!O38 -> 0 | U4: =AU!R38 -> 0 | V4: =AU!U38 -> 0 | W4: =AU!X38 -> 0 | X4: =AU!AA38 -> 0 | Y4: =AU!AD38 -> 0 | Z4: =AU!AG38 -> 0 | AA4: =AU!AJ38 -> 0 | AB4: =AU!AM38 -> 0 | AC4: =SUM(S4:AB4) -> 0
B5: =AU!C21 -> Postdoc | C5: =IF(AU!F21=0,"",AU!F21) | D5: =AU!L21 -> 0 | E5: =AU!O21 -> 12 | F5: =AU!R21 -> 12 | G5: =AU!U21 -> 12 | H5: =AU!X21 -> 0 | I5: =AU!AA21 -> 0 | J5: =AU!AD21 -> 0 | K5: =AU!AG21 -> 0 | L5: =AU!AJ21 -> 0 | M5: =AU!AM21 -> 0 | N5: =SUM(D5:M5) -> 36 | Q5: =AU!C39 -> - | R5: =IF(AU!F39=0,"",AU!F39) | S5: =AU!L39 -> 0 | T5: =AU!O39 -> 0 | U5: =AU!R39 -> 0 | V5: =AU!U39 -> 0 | W5: =AU!X39 -> 0 | X5: =AU!AA39 -> 0 | Y5: =AU!AD39 -> 0 | Z5: =AU!AG39 -> 0 | AA5: =AU!AJ39 -> 0 | AB5: =AU!AM39 -> 0 | AC5: =SUM(S5:AB5) -> 0
B6: =AU!C22 -> Postdoc | C6: =IF(AU!F22=0,"",AU!F22) | D6: =AU!L22 -> 0 | E6: =AU!O22 -> 0 | F6: =AU!R22 -> 6 | G6: =AU!U22 -> 12 | H6: =AU!X22 -> 12 | I6: =AU!AA22 -> 6 | J6: =AU!AD22 -> 0 | K6: =AU!AG22 -> 0 | L6: =AU!AJ22 -> 0 | M6: =AU!AM22 -> 0 | N6: =SUM(D6:M6) -> 36 | Q6: =AU!C40 -> - | R6: =IF(AU!F40=0,"",AU!F40) | S6: =AU!L40 -> 0 | T6: =AU!O40 -> 0 | U6: =AU!R40 -> 0 | V6: =AU!U40 -> 0 | W6: =AU!X40 -> 0 | X6: =AU!AA40 -> 0 | Y6: =AU!AD40 -> 0 | Z6: =AU!AG40 -> 0 | AA6: =AU!AJ40 -> 0 | AB6: =AU!AM40 -> 0 | AC6: =SUM(S6:AB6) -> 0
B7: =AU!C23 -> PhD Student | C7: =IF(AU!F23=0,"",AU!F23) | D7: =AU!L23 -> 6 | E7: =AU!O23 -> 12 | F7: =AU!R23 -> 12 | G7: =AU!U23 -> 6 | H7: =AU!X23 -> 0 | I7: =AU!AA23 -> 0 | J7: =AU!AD23 -> 0 | K7: =AU!AG23 -> 0 | L7: =AU!AJ23 -> 0 | M7: =AU!AM23 -> 0 | N7: =SUM(D7:M7) -> 36 | Q7: =AU!C41 -> - | R7: =IF(AU!F41=0,"",AU!F41) | S7: =AU!L41 -> 0 | T7: =AU!O41 -> 0 | U7: =AU!R41 -> 0 | V7: =AU!U41 -> 0 | W7: =AU!X41 -> 0 | X7: =AU!AA41 -> 0 | Y7: =AU!AD41 -> 0 | Z7: =AU!AG41 -> 0 | AA7: =AU!AJ41 -> 0 | AB7: =AU!AM41 -> 0 | AC7: =SUM(S7:AB7) -> 0
B8: =AU!C24 -> PhD Student | C8: =IF(AU!F24=0,"",AU!F24) | D8: =AU!L24 -> 0 | E8: =AU!O24 -> 0 | F8: =AU!R24 -> 6 | G8: =AU!U24 -> 12 | H8: =AU!X24 -> 12 | I8: =AU!AA24 -> 6 | J8: =AU!AD24 -> 0 | K8: =AU!AG24 -> 0 | L8: =AU!AJ24 -> 0 | M8: =AU!AM24 -> 0 | N8: =SUM(D8:M8) -> 36 | Q8: =AU!C42 -> - | R8: =IF(AU!F42=0,"",AU!F42) | S8: =AU!L42 -> 0 | T8: =AU!O42 -> 0 | U8: =AU!R42 -> 0 | V8: =AU!U42 -> 0 | W8: =AU!X42 -> 0 | X8: =AU!AA42 -> 0 | Y8: =AU!AD42 -> 0 | Z8: =AU!AG42 -> 0 | AA8: =AU!AJ42 -> 0 | AB8: =AU!AM42 -> 0 | AC8: =SUM(S8:AB8) -> 0
B9: =AU!C25 -> - | C9: =IF(AU!F25=0,"",AU!F25) | D9: =AU!L25 -> 0 | E9: =AU!O25 -> 0 | F9: =AU!R25 -> 0 | G9: =AU!U25 -> 0 | H9: =AU!X25 -> 0 | I9: =AU!AA25 -> 0 | J9: =AU!AD25 -> 0 | K9: =AU!AG25 -> 0 | L9: =AU!AJ25 -> 0 | M9: =AU!AM25 -> 0 | N9: =SUM(D9:M9) -> 0 | Q9: =AU!C43 -> - | R9: =IF(AU!F43=0,"",AU!F43) | S9: =AU!L43 -> 0 | T9: =AU!O43 -> 0 | U9: =AU!R43 -> 0 | V9: =AU!U43 -> 0 | W9: =AU!X43 -> 0 | X9: =AU!AA43 -> 0 | Y9: =AU!AD43 -> 0 | Z9: =AU!AG43 -> 0 | AA9: =AU!AJ43 -> 0 | AB9: =AU!AM43 -> 0 | AC9: =SUM(S9:AB9) -> 0
B10: =AU!C26 -> - | C10: =IF(AU!F26=0,"",AU!F26) | D10: =AU!L26 -> 0 | E10: =AU!O26 -> 0 | F10: =AU!R26 -> 0 | G10: =AU!U26 -> 0 | H10: =AU!X26 -> 0 | I10: =AU!AA26 -> 0 | J10: =AU!AD26 -> 0 | K10: =AU!AG26 -> 0 | L10: =AU!AJ26 -> 0 | M10: =AU!AM26 -> 0 | N10: =SUM(D10:M10) -> 0 | Q10: =AU!C44 -> - | R10: =IF(AU!F44=0,"",AU!F44) | S10: =AU!L44 -> 0 | T10: =AU!O44 -> 0 | U10: =AU!R44 -> 0 | V10: =AU!U44 -> 0 | W10: =AU!X44 -> 0 | X10: =AU!AA44 -> 0 | Y10: =AU!AD44 -> 0 | Z10: =AU!AG44 -> 0 | AA10: =AU!AJ44 -> 0 | AB10: =AU!AM44 -> 0 | AC10: =SUM(S10:AB10) -> 0
B11: =AU!C27 -> - | C11: =IF(AU!F27=0,"",AU!F27) | D11: =AU!L27 -> 0 | E11: =AU!O27 -> 0 | F11: =AU!R27 -> 0 | G11: =AU!U27 -> 0 | H11: =AU!X27 -> 0 | I11: =AU!AA27 -> 0 | J11: =AU!AD27 -> 0 | K11: =AU!AG27 -> 0 | L11: =AU!AJ27 -> 0 | M11: =AU!AM27 -> 0 | N11: =SUM(D11:M11) -> 0 | Q11: =AU!C45 -> - | R11: =IF(AU!F45=0,"",AU!F45) | S11: =AU!L45 -> 0 | T11: =AU!O45 -> 0 | U11: =AU!R45 -> 0 | V11: =AU!U45 -> 0 | W11: =AU!X45 -> 0 | X11: =AU!AA45 -> 0 | Y11: =AU!AD45 -> 0 | Z11: =AU!AG45 -> 0 | AA11: =AU!AJ45 -> 0 | AB11: =AU!AM45 -> 0 | AC11: =SUM(S11:AB11) -> 0
B12: =AU!C28 -> - | C12: =IF(AU!F28=0,"",AU!F28) | D12: =AU!L28 -> 0 | E12: =AU!O28 -> 0 | F12: =AU!R28 -> 0 | G12: =AU!U28 -> 0 | H12: =AU!X28 -> 0 | I12: =AU!AA28 -> 0 | J12: =AU!AD28 -> 0 | K12: =AU!AG28 -> 0 | L12: =AU!AJ28 -> 0 | M12: =AU!AM28 -> 0 | N12: =SUM(D12:M12) -> 0 | Q12: =AU!C46 -> - | R12: =IF(AU!F46=0,"",AU!F46) | S12: =AU!L46 -> 0 | T12: =AU!O46 -> 0 | U12: =AU!R46 -> 0 | V12: =AU!U46 -> 0 | W12: =AU!X46 -> 0 | X12: =AU!AA46 -> 0 | Y12: =AU!AD46 -> 0 | Z12: =AU!AG46 -> 0 | AA12: =AU!AJ46 -> 0 | AB12: =AU!AM46 -> 0 | AC12: =SUM(S12:AB12) -> 0
B13: =AU!C29 -> - | C13: =IF(AU!F29=0,"",AU!F29) | D13: =AU!L29 -> 0 | E13: =AU!O29 -> 0 | F13: =AU!R29 -> 0 | G13: =AU!U29 -> 0 | H13: =AU!X29 -> 0 | I13: =AU!AA29 -> 0 | J13: =AU!AD29 -> 0 | K13: =AU!AG29 -> 0 | L13: =AU!AJ29 -> 0 | M13: =AU!AM29 -> 0 | N13: =SUM(D13:M13) -> 0 | Q13: =AU!C47 -> - | R13: =IF(AU!F47=0,"",AU!F47) | S13: =AU!L47 -> 0 | T13: =AU!O47 -> 0 | U13: =AU!R47 -> 0 | V13: =AU!U47 -> 0 | W13: =AU!X47 -> 0 | X13: =AU!AA47 -> 0 | Y13: =AU!AD47 -> 0 | Z13: =AU!AG47 -> 0 | AA13: =AU!AJ47 -> 0 | AB13: =AU!AM47 -> 0 | AC13: =SUM(S13:AB13) -> 0
B14: =AU!C30 -> - | C14: =IF(AU!F30=0,"",AU!F30) | D14: =AU!L30 -> 0 | E14: =AU!O30 -> 0 | F14: =AU!R30 -> 0 | G14: =AU!U30 -> 0 | H14: =AU!X30 -> 0 | I14: =AU!AA30 -> 0 | J14: =AU!AD30 -> 0 | K14: =AU!AG30 -> 0 | L14: =AU!AJ30 -> 0 | M14: =AU!AM30 -> 0 | N14: =SUM(D14:M14) -> 0 | Q14: =AU!C48 -> - | R14: =IF(AU!F48=0,"",AU!F48) | S14: =AU!L48 -> 0 | T14: =AU!O48 -> 0 | U14: =AU!R48 -> 0 | V14: =AU!U48 -> 0 | W14: =AU!X48 -> 0 | X14: =AU!AA48 -> 0 | Y14: =AU!AD48 -> 0 | Z14: =AU!AG48 -> 0 | AA14: =AU!AJ48 -> 0 | AB14: =AU!AM48 -> 0 | AC14: =SUM(S14:AB14) -> 0
B15: =AU!C31 -> - | C15: =IF(AU!F31=0,"",AU!F31) | D15: =AU!L31 -> 0 | E15: =AU!O31 -> 0 | F15: =AU!R31 -> 0 | G15: =AU!U31 -> 0 | H15: =AU!X31 -> 0 | I15: =AU!AA31 -> 0 | J15: =AU!AD31 -> 0 | K15: =AU!AG31 -> 0 | L15: =AU!AJ31 -> 0 | M15: =AU!AM31 -> 0 | N15: =SUM(D15:M15) -> 0 | Q15: =AU!C49 -> - | R15: =IF(AU!F49=0,"",AU!F49) | S15: =AU!L49 -> 0 | T15: =AU!O49 -> 0 | U15: =AU!R49 -> 0 | V15: =AU!U49 -> 0 | W15: =AU!X49 -> 0 | X15: =AU!AA49 -> 0 | Y15: =AU!AD49 -> 0 | Z15: =AU!AG49 -> 0 | AA15: =AU!AJ49 -> 0 | AB15: =AU!AM49 -> 0 | AC15: =SUM(S15:AB15) -> 0
... B19: =AU!C35 -> - | C19: =IF(AU!F35=0,"",AU!F35) | D19: =AU!L35 -> 0 | E19: =AU!O35 -> 0 | F19: =AU!R35 -> 0 | G19: =AU!U35 -> 0 | H19: =AU!X35 -> 0 | I19: =AU!AA35 -> 0 | J19: =AU!AD35 -> 0 | K19: =AU!AG35 -> 0 | L19: =AU!AJ35 -> 0 | M19: =AU!AM35 -> 0 | N19: =SUM(D19:M19) -> 0 | Q19: =AU!C53 -> - | R19: =IF(AU!F53=0,"",AU!F53) | S19: =AU!L53 -> 0 | T19: =AU!O53 -> 0 | U19: =AU!R53 -> 0 | V19: =AU!U53 -> 0 | W19: =AU!X53 -> 0 | X19: =AU!AA53 -> 0 | Y19: =AU!AD53 -> 0 | Z19: =AU!AG53 -> 0 | AA19: =AU!AJ53 -> 0 | AB19: =AU!AM53 -> 0 | AC19: =SUM(S19:AB19) -> 0
B20: =AU!C55& " Man months" -> 1. TAP Man months | Q20: =B20 -> 1. TAP Man months
B21: =AU!C56 -> AC staff et al. | C21: =IF(AU!F56=0,"",AU!F56) | D21: =AU!L56 -> 0 | E21: =AU!O56 -> 0 | F21: =AU!R56 -> 0 | G21: =AU!U56 -> 0 | H21: =AU!X56 -> 0 | I21: =AU!AA56 -> 0 | J21: =AU!AD56 -> 0 | K21: =AU!AG56 -> 0 | L21: =AU!AJ56 -> 0 | M21: =AU!AM56 -> 0 | N21: =SUM(D21:M21) -> 0 | Q21: =AU!C74 -> - | R21: =IF(AU!F74=0,"",AU!F74) | S21: =AU!L74 -> 0 | T21: =AU!O74 -> 0 | U21: =AU!R74 -> 0 | V21: =AU!U74 -> 0 | W21: =AU!X74 -> 0 | X21: =AU!AA74 -> 0 | Y21: =AU!AD74 -> 0 | Z21: =AU!AG74 -> 0 | AA21: =AU!AJ74 -> 0 | AB21: =AU!AM74 -> 0 | AC21: =SUM(S21:AB21) -> 0
B22: =AU!C57 -> - | C22: =IF(AU!F57=0,"",AU!F57) | D22: =AU!L57 -> 0 | E22: =AU!O57 -> 0 | F22: =AU!R57 -> 0 | G22: =AU!U57 -> 0 | H22: =AU!X57 -> 0 | I22: =AU!AA57 -> 0 | J22: =AU!AD57 -> 0 | K22: =AU!AG57 -> 0 | L22: =AU!AJ57 -> 0 | M22: =AU!AM57 -> 0 | N22: =SUM(D22:M22) -> 0 | Q22: =AU!C75 -> - | R22: =IF(AU!F75=0,"",AU!F75) | S22: =AU!L75 -> 0 | T22: =AU!O75 -> 0 | U22: =AU!R75 -> 0 | V22: =AU!U75 -> 0 | W22: =AU!X75 -> 0 | X22: =AU!AA75 -> 0 | Y22: =AU!AD75 -> 0 | Z22: =AU!AG75 -> 0 | AA22: =AU!AJ75 -> 0 | AB22: =AU!AM75 -> 0 | AC22: =SUM(S22:AB22) -> 0
B23: =AU!C58 -> - | C23: =IF(AU!F58=0,"",AU!F58) | D23: =AU!L58 -> 0 | E23: =AU!O58 -> 0 | F23: =AU!R58 -> 0 | G23: =AU!U58 -> 0 | H23: =AU!X58 -> 0 | I23: =AU!AA58 -> 0 | J23: =AU!AD58 -> 0 | K23: =AU!AG58 -> 0 | L23: =AU!AJ58 -> 0 | M23: =AU!AM58 -> 0 | N23: =SUM(D23:M23) -> 0 | Q23: =AU!C76 -> - | R23: =IF(AU!F76=0,"",AU!F76) | S23: =AU!L76 -> 0 | T23: =AU!O76 -> 0 | U23: =AU!R76 -> 0 | V23: =AU!U76 -> 0 | W23: =AU!X76 -> 0 | X23: =AU!AA76 -> 0 | Y23: =AU!AD76 -> 0 | Z23: =AU!AG76 -> 0 | AA23: =AU!AJ76 -> 0 | AB23: =AU!AM76 -> 0 | AC23: =SUM(S23:AB23) -> 0
B24: =AU!C59 -> - | C24: =IF(AU!F59=0,"",AU!F59) | D24: =AU!L59 -> 0 | E24: =AU!O59 -> 0 | F24: =AU!R59 -> 0 | G24: =AU!U59 -> 0 | H24: =AU!X59 -> 0 | I24: =AU!AA59 -> 0 | J24: =AU!AD59 -> 0 | K24: =AU!AG59 -> 0 | L24: =AU!AJ59 -> 0 | M24: =AU!AM59 -> 0 | N24: =SUM(D24:M24) -> 0 | Q24: =AU!C77 -> - | R24: =IF(AU!F77=0,"",AU!F77) | S24: =AU!L77 -> 0 | T24: =AU!O77 -> 0 | U24: =AU!R77 -> 0 | V24: =AU!U77 -> 0 | W24: =AU!X77 -> 0 | X24: =AU!AA77 -> 0 | Y24: =AU!AD77 -> 0 | Z24: =AU!AG77 -> 0 | AA24: =AU!AJ77 -> 0 | AB24: =AU!AM77 -> 0 | AC24: =SUM(S24:AB24) -> 0
B25: =AU!C60 -> - | C25: =IF(AU!F60=0,"",AU!F60) | D25: =AU!L60 -> 0 | E25: =AU!O60 -> 0 | F25: =AU!R60 -> 0 | G25: =AU!U60 -> 0 | H25: =AU!X60 -> 0 | I25: =AU!AA60 -> 0 | J25: =AU!AD60 -> 0 | K25: =AU!AG60 -> 0 | L25: =AU!AJ60 -> 0 | M25: =AU!AM60 -> 0 | N25: =SUM(D25:M25) -> 0 | Q25: =AU!C78 -> - | R25: =IF(AU!F78=0,"",AU!F78) | S25: =AU!L78 -> 0 | T25: =AU!O78 -> 0 | U25: =AU!R78 -> 0 | V25: =AU!U78 -> 0 | W25: =AU!X78 -> 0 | X25: =AU!AA78 -> 0 | Y25: =AU!AD78 -> 0 | Z25: =AU!AG78 -> 0 | AA25: =AU!AJ78 -> 0 | AB25: =AU!AM78 -> 0 | AC25: =SUM(S25:AB25) -> 0
B26: =AU!C61 -> - | C26: =IF(AU!F61=0,"",AU!F61) | D26: =AU!L61 -> 0 | E26: =AU!O61 -> 0 | F26: =AU!R61 -> 0 | G26: =AU!U61 -> 0 | H26: =AU!X61 -> 0 | I26: =AU!AA61 -> 0 | J26: =AU!AD61 -> 0 | K26: =AU!AG61 -> 0 | L26: =AU!AJ61 -> 0 | M26: =AU!AM61 -> 0 | N26: =SUM(D26:M26) -> 0 | Q26: =AU!C79 -> - | R26: =IF(AU!F79=0,"",AU!F79) | S26: =AU!L79 -> 0 | T26: =AU!O79 -> 0 | U26: =AU!R79 -> 0 | V26: =AU!U79 -> 0 | W26: =AU!X79 -> 0 | X26: =AU!AA79 -> 0 | Y26: =AU!AD79 -> 0 | Z26: =AU!AG79 -> 0 | AA26: =AU!AJ79 -> 0 | AB26: =AU!AM79 -> 0 | AC26: =SUM(S26:AB26) -> 0
B27: =AU!C62 -> - | C27: =IF(AU!F62=0,"",AU!F62) | D27: =AU!L62 -> 0 | E27: =AU!O62 -> 0 | F27: =AU!R62 -> 0 | G27: =AU!U62 -> 0 | H27: =AU!X62 -> 0 | I27: =AU!AA62 -> 0 | J27: =AU!AD62 -> 0 | K27: =AU!AG62 -> 0 | L27: =AU!AJ62 -> 0 | M27: =AU!AM62 -> 0 | N27: =SUM(D27:M27) -> 0 | Q27: =AU!C80 -> - | R27: =IF(AU!F80=0,"",AU!F80) | S27: =AU!L80 -> 0 | T27: =AU!O80 -> 0 | U27: =AU!R80 -> 0 | V27: =AU!U80 -> 0 | W27: =AU!X80 -> 0 | X27: =AU!AA80 -> 0 | Y27: =AU!AD80 -> 0 | Z27: =AU!AG80 -> 0 | AA27: =AU!AJ80 -> 0 | AB27: =AU!AM80 -> 0 | AC27: =SUM(S27:AB27) -> 0
B28: =AU!C63 -> - | C28: =IF(AU!F63=0,"",AU!F63) | D28: =AU!L63 -> 0 | E28: =AU!O63 -> 0 | F28: =AU!R63 -> 0 | G28: =AU!U63 -> 0 | H28: =AU!X63 -> 0 | I28: =AU!AA63 -> 0 | J28: =AU!AD63 -> 0 | K28: =AU!AG63 -> 0 | L28: =AU!AJ63 -> 0 | M28: =AU!AM63 -> 0 | N28: =SUM(D28:M28) -> 0 | Q28: =AU!C81 -> - | R28: =IF(AU!F81=0,"",AU!F81) | S28: =AU!L81 -> 0 | T28: =AU!O81 -> 0 | U28: =AU!R81 -> 0 | V28: =AU!U81 -> 0 | W28: =AU!X81 -> 0 | X28: =AU!AA81 -> 0 | Y28: =AU!AD81 -> 0 | Z28: =AU!AG81 -> 0 | AA28: =AU!AJ81 -> 0 | AB28: =AU!AM81 -> 0 | AC28: =SUM(S28:AB28) -> 0
B29: =AU!C64 -> - | C29: =IF(AU!F64=0,"",AU!F64) | D29: =AU!L64 -> 0 | E29: =AU!O64 -> 0 | F29: =AU!R64 -> 0 | G29: =AU!U64 -> 0 | H29: =AU!X64 -> 0 | I29: =AU!AA64 -> 0 | J29: =AU!AD64 -> 0 | K29: =AU!AG64 -> 0 | L29: =AU!AJ64 -> 0 | M29: =AU!AM64 -> 0 | N29: =SUM(D29:M29) -> 0 | Q29: =AU!C82 -> - | R29: =IF(AU!F82=0,"",AU!F82) | S29: =AU!L82 -> 0 | T29: =AU!O82 -> 0 | U29: =AU!R82 -> 0 | V29: =AU!U82 -> 0 | W29: =AU!X82 -> 0 | X29: =AU!AA82 -> 0 | Y29: =AU!AD82 -> 0 | Z29: =AU!AG82 -> 0 | AA29: =AU!AJ82 -> 0 | AB29: =AU!AM82 -> 0 | AC29: =SUM(S29:AB29) -> 0
B30: =AU!C65 -> - | C30: =IF(AU!F65=0,"",AU!F65) | D30: =AU!L65 -> 0 | E30: =AU!O65 -> 0 | F30: =AU!R65 -> 0 | G30: =AU!U65 -> 0 | H30: =AU!X65 -> 0 | I30: =AU!AA65 -> 0 | J30: =AU!AD65 -> 0 | K30: =AU!AG65 -> 0 | L30: =AU!AJ65 -> 0 | M30: =AU!AM65 -> 0 | N30: =SUM(D30:M30) -> 0 | Q30: =AU!C83 -> - | R30: =IF(AU!F83=0,"",AU!F83) | S30: =AU!L83 -> 0 | T30: =AU!O83 -> 0 | U30: =AU!R83 -> 0 | V30: =AU!U83 -> 0 | W30: =AU!X83 -> 0 | X30: =AU!AA83 -> 0 | Y30: =AU!AD83 -> 0 | Z30: =AU!AG83 -> 0 | AA30: =AU!AJ83 -> 0 | AB30: =AU!AM83 -> 0 | AC30: =SUM(S30:AB30) -> 0
B31: =AU!C66 -> - | C31: =IF(AU!F66=0,"",AU!F66) | D31: =AU!L66 -> 0 | E31: =AU!O66 -> 0 | F31: =AU!R66 -> 0 | G31: =AU!U66 -> 0 | H31: =AU!X66 -> 0 | I31: =AU!AA66 -> 0 | J31: =AU!AD66 -> 0 | K31: =AU!AG66 -> 0 | L31: =AU!AJ66 -> 0 | M31: =AU!AM66 -> 0 | N31: =SUM(D31:M31) -> 0 | Q31: =AU!C84 -> - | R31: =IF(AU!F84=0,"",AU!F84) | S31: =AU!L84 -> 0 | T31: =AU!O84 -> 0 | U31: =AU!R84 -> 0 | V31: =AU!U84 -> 0 | W31: =AU!X84 -> 0 | X31: =AU!AA84 -> 0 | Y31: =AU!AD84 -> 0 | Z31: =AU!AG84 -> 0 | AA31: =AU!AJ84 -> 0 | AB31: =AU!AM84 -> 0 | AC31: =SUM(S31:AB31) -> 0
B32: =AU!C67 -> - | C32: =IF(AU!F67=0,"",AU!F67) | D32: =AU!L67 -> 0 | E32: =AU!O67 -> 0 | F32: =AU!R67 -> 0 | G32: =AU!U67 -> 0 | H32: =AU!X67 -> 0 | I32: =AU!AA67 -> 0 | J32: =AU!AD67 -> 0 | K32: =AU!AG67 -> 0 | L32: =AU!AJ67 -> 0 | M32: =AU!AM67 -> 0 | N32: =SUM(D32:M32) -> 0 | Q32: =AU!C85 -> - | R32: =IF(AU!F85=0,"",AU!F85) | S32: =AU!L85 -> 0 | T32: =AU!O85 -> 0 | U32: =AU!R85 -> 0 | V32: =AU!U85 -> 0 | W32: =AU!X85 -> 0 | X32: =AU!AA85 -> 0 | Y32: =AU!AD85 -> 0 | Z32: =AU!AG85 -> 0 | AA32: =AU!AJ85 -> 0 | AB32: =AU!AM85 -> 0 | AC32: =SUM(S32:AB32) -> 0
... B36: =AU!C71 -> - | C36: =IF(AU!F71=0,"",AU!F71) | D36: =AU!L71 -> 0 | E36: =AU!O71 -> 0 | F36: =AU!R71 -> 0 | G36: =AU!U71 -> 0 | H36: =AU!X71 -> 0 | I36: =AU!AA71 -> 0 | J36: =AU!AD71 -> 0 | K36: =AU!AG71 -> 0 | L36: =AU!AJ71 -> 0 | M36: =AU!AM71 -> 0 | N36: =SUM(D36:M36) -> 0 | Q36: =AU!C89 -> - | R36: =IF(AU!F89=0,"",AU!F89) | S36: =AU!L89 -> 0 | T36: =AU!O89 -> 0 | U36: =AU!R89 -> 0 | V36: =AU!U89 -> 0 | W36: =AU!X89 -> 0 | X36: =AU!AA89 -> 0 | Y36: =AU!AD89 -> 0 | Z36: =AU!AG89 -> 0 | AA36: =AU!AJ89 -> 0 | AB36: =AU!AM89 -> 0 | AC36: =SUM(S36:AB36) -> 0
B37: Total | D37: =SUM(D4:D36) -> 18 | E37: =SUM(E4:E36) -> 36 | F37: =SUM(F4:F36) -> 48 | G37: =SUM(G4:G36) -> 42 | H37: =SUM(H4:H36) -> 24 | I37: =SUM(I4:I36) -> 12 | J37: =SUM(J4:J36) -> 0 | K37: =SUM(K4:K36) -> 0 | ... N37: =SUM(N4:N36) -> 180 | Q37: Total | S37: =SUM(S4:S36) -> 0 | T37: =SUM(T4:T36) -> 0 | U37: =SUM(U4:U36) -> 0 | V37: =SUM(V4:V36) -> 0 | W37: =SUM(W4:W36) -> 0 | X37: =SUM(X4:X36) -> 0 | Y37: =SUM(Y4:Y36) -> 0 | Z37: =SUM(Z4:Z36) -> 0 | ... AC37: =SUM(AC4:AC36) -> 0
B39: =AU!C19&" Salary costs " -> 1. VIP Salary costs | D39: =AU!L15 -> Year 1 | E39: =AU!O15 -> Year 2 | F39: =AU!R15 -> Year 3 | G39: =AU!U15 -> Year 4 | H39: =AU!X15 -> Year 5 | I39: =AU!AA15 -> Year 6 | J39: =AU!AD15 -> Year 7 | K39: =AU!AG15 -> Year 8 | L39: =AU!AJ15 -> Year 9 | M39: =AU!AM15 -> Year 10 | N39: Total | Q39: =B39 -> 1. VIP Salary costs | S39: =AU!L15 -> Year 1 | T39: =AU!O15 -> Year 2 | U39: =AU!R15 -> Year 3 | V39: =AU!U15 -> Year 4 | W39: =AU!X15 -> Year 5 | X39: =AU!AA15 -> Year 6 | Y39: =AU!AD15 -> Year 7 | Z39: =AU!AG15 -> Year 8 | AA39: =AU!AJ15 -> Year 9 | AB39: =AU!AM15 -> Year 10 | AC39: Total
